Workbook

Sheet Dashboard
B1: DRA MEETING | CUDDALORE DISTRICT | O1: Report period
B2: Application disposal review: NISD, ISD and F-Line (Rural, Natham, Urban). Everything on this sheet is calculated from the data sheets. | O2: 1 to 30 September 2026
B4: Applications handled | E4: Disposed | J4: Pending | N4: Pending beyond time limit
B5: =SUM(Calc!B3:B11) -> 25422 | E5: =IFERROR(SUM(Calc!C3:C11)/SUM(Calc!B3:B11),0) -> 0.60207694 | J5: =SUM(Calc!D3:D11) -> 10116 | N5: =SUM(Calc!F3:F11) -> 1564
B6: ="all 9 streams combined" -> all 9 streams combined | E6: =TEXT(SUM(Calc!C3:C11),"#,##0")&" of "&TEXT(SUM(Calc!B3:B11),"#,##0") -> 15,306 of 25,422 | J6: =TEXT(IFERROR(SUM(Calc!D3:D11)/SUM(Calc!B3:B11),0),"0%")&" of workload" -> 40% of workload | N6: ="NISD 15 days; ISD, F-Line 1 month" -> NISD 15 days; ISD, F-Line 1 month
B8: 1. Disposal by application stream (worst to best) | I8: 2. Taluk-wise disposal % by stream (taluks ranked worst to best)
B9: Stream | C9: Total | D9: Disposed | E9: Pending | F9: Disposal % | G9: Beyond limit | I9: Rank | J9: Taluk | K9: NISD Rural | L9: NISD Natham | M9: ISD Rural | N9: ISD Natham | O9: F-Line Rural | P9: F-Line Natham | Q9: Pending % (6 streams) | R9: Pending count
B10: =INDEX(Calc!$A$3:$A$11,MATCH(SMALL(Calc!$H$3:$H$11,1),Calc!$H$3:$H$11,0)) -> F-Line Urban | C10: =INDEX(Calc!$B$3:$B$11,MATCH(SMALL(Calc!$H$3:$H$11,1),Calc!$H$3:$H$11,0)) -> 182 | D10: =INDEX(Calc!$C$3:$C$11,MATCH(SMALL(Calc!$H$3:$H$11,1),Calc!$H$3:$H$11,0)) -> 64 | E10: =INDEX(Calc!$D$3:$D$11,MATCH(SMALL(Calc!$H$3:$H$11,1),Calc!$H$3:$H$11,0)) -> 118 | F10: =INDEX(Calc!$G$3:$G$11,MATCH(SMALL(Calc!$H$3:$H$11,1),Calc!$H$3:$H$11,0)) -> 0.35164835 | G10: =INDEX(Calc!$F$3:$F$11,MATCH(SMALL(Calc!$H$3:$H$11,1),Calc!$H$3:$H$11,0)) -> 40 | I10: 1 | J10: =INDEX(Calc!$A$15:$A$24,MATCH(LARGE(Calc!$Q$15:$Q$24,1),Calc!$Q$15:$Q$24,0)) -> Kattumannarkoil | K10: =INDEX(Calc!$R$15:$R$24,MATCH(LARGE(Calc!$Q$15:$Q$24,1),Calc!$Q$15:$Q$24,0)) -> 0.78061224 | L10: =INDEX(Calc!$S$15:$S$24,MATCH(LARGE(Calc!$Q$15:$Q$24,1),Calc!$Q$15:$Q$24,0)) -> 0.71551724 | M10: =INDEX(Calc!$T$15:$T$24,MATCH(LARGE(Calc!$Q$15:$Q$24,1),Calc!$Q$15:$Q$24,0)) -> 0.50290698 | N10: =INDEX(Calc!$U$15:$U$24,MATCH(LARGE(Calc!$Q$15:$Q$24,1),Calc!$Q$15:$Q$24,0)) -> 0.44 | O10: =INDEX(Calc!$V$15:$V$24,MATCH(LARGE(Calc!$Q$15:$Q$24,1),Calc!$Q$15:$Q$24,0)) -> 0.359447 | P10: =INDEX(Calc!$W$15:$W$24,MATCH(LARGE(Calc!$Q$15:$Q$24,1),Calc!$Q$15:$Q$24,0)) -> 0.36507937 | Q10: =INDEX(Calc!$P$15:$P$24,MATCH(LARGE(Calc!$Q$15:$Q$24,1),Calc!$Q$15:$Q$24,0)) -> 0.4197901 | R10: =INDEX(Calc!$O$15:$O$24,MATCH(LARGE(Calc!$Q$15:$Q$24,1),Calc!$Q$15:$Q$24,0)) -> 840
B11: =INDEX(Calc!$A$3:$A$11,MATCH(SMALL(Calc!$H$3:$H$11,2),Calc!$H$3:$H$11,0)) -> F-Line Natham | C11: =INDEX(Calc!$B$3:$B$11,MATCH(SMALL(Calc!$H$3:$H$11,2),Calc!$H$3:$H$11,0)) -> 1597 | D11: =INDEX(Calc!$C$3:$C$11,MATCH(SMALL(Calc!$H$3:$H$11,2),Calc!$H$3:$H$11,0)) -> 596 | E11: =INDEX(Calc!$D$3:$D$11,MATCH(SMALL(Calc!$H$3:$H$11,2),Calc!$H$3:$H$11,0)) -> 1001 | F11: =INDEX(Calc!$G$3:$G$11,MATCH(SMALL(Calc!$H$3:$H$11,2),Calc!$H$3:$H$11,0)) -> 0.37319975 | G11: =INDEX(Calc!$F$3:$F$11,MATCH(SMALL(Calc!$H$3:$H$11,2),Calc!$H$3:$H$11,0)) -> 472 | I11: 2 | J11: =INDEX(Calc!$A$15:$A$24,MATCH(LARGE(Calc!$Q$15:$Q$24,2),Calc!$Q$15:$Q$24,0)) -> Srimushnam | K11: =INDEX(Calc!$R$15:$R$24,MATCH(LARGE(Calc!$Q$15:$Q$24,2),Calc!$Q$15:$Q$24,0)) -> 0.77014925 | L11: =INDEX(Calc!$S$15:$S$24,MATCH(LARGE(Calc!$Q$15:$Q$24,2),Calc!$Q$15:$Q$24,0)) -> 0.728 | M11: =INDEX(Calc!$T$15:$T$24,MATCH(LARGE(Calc!$Q$15:$Q$24,2),Calc!$Q$15:$Q$24,0)) -> 0.5372549 | N11: =INDEX(Calc!$U$15:$U$24,MATCH(LARGE(Calc!$Q$15:$Q$24,2),Calc!$Q$15:$Q$24,0)) -> 0.48648649 | O11: =INDEX(Calc!$V$15:$V$24,MATCH(LARGE(Calc!$Q$15:$Q$24,2),Calc!$Q$15:$Q$24,0)) -> 0.37037037 | P11: =INDEX(Calc!$W$15:$W$24,MATCH(LARGE(Calc!$Q$15:$Q$24,2),Calc!$Q$15:$Q$24,0)) -> 0.34693878 | Q11: =INDEX(Calc!$P$15:$P$24,MATCH(LARGE(Calc!$Q$15:$Q$24,2),Calc!$Q$15:$Q$24,0)) -> 0.41821561 | R11: =INDEX(Calc!$O$15:$O$24,MATCH(LARGE(Calc!$Q$15:$Q$24,2),Calc!$Q$15:$Q$24,0)) -> 450
B12: =INDEX(Calc!$A$3:$A$11,MATCH(SMALL(Calc!$H$3:$H$11,3),Calc!$H$3:$H$11,0)) -> F-Line Rural | C12: =INDEX(Calc!$B$3:$B$11,MATCH(SMALL(Calc!$H$3:$H$11,3),Calc!$H$3:$H$11,0)) -> 3205 | D12: =INDEX(Calc!$C$3:$C$11,MATCH(SMALL(Calc!$H$3:$H$11,3),Calc!$H$3:$H$11,0)) -> 1258 | E12: =INDEX(Calc!$D$3:$D$11,MATCH(SMALL(Calc!$H$3:$H$11,3),Calc!$H$3:$H$11,0)) -> 1947 | F12: =INDEX(Calc!$G$3:$G$11,MATCH(SMALL(Calc!$H$3:$H$11,3),Calc!$H$3:$H$11,0)) -> 0.3925117 | G12: =INDEX(Calc!$F$3:$F$11,MATCH(SMALL(Calc!$H$3:$H$11,3),Calc!$H$3:$H$11,0)) -> 1005 | I12: 3 | J12: =INDEX(Calc!$A$15:$A$24,MATCH(LARGE(Calc!$Q$15:$Q$24,3),Calc!$Q$15:$Q$24,0)) -> Panruti | K12: =INDEX(Calc!$R$15:$R$24,MATCH(LARGE(Calc!$Q$15:$Q$24,3),Calc!$Q$15:$Q$24,0)) -> 0.73668033 | L12: =INDEX(Calc!$S$15:$S$24,MATCH(LARGE(Calc!$Q$15:$Q$24,3),Calc!$Q$15:$Q$24,0)) -> 0.75064267 | M12: =INDEX(Calc!$T$15:$T$24,MATCH(LARGE(Calc!$Q$15:$Q$24,3),Calc!$Q$15:$Q$24,0)) -> 0.51262136 | N12: =INDEX(Calc!$U$15:$U$24,MATCH(LARGE(Calc!$Q$15:$Q$24,3),Calc!$Q$15:$Q$24,0)) -> 0.53586498 | O12: =INDEX(Calc!$V$15:$V$24,MATCH(LARGE(Calc!$Q$15:$Q$24,3),Calc!$Q$15:$Q$24,0)) -> 0.34316354 | P12: =INDEX(Calc!$W$15:$W$24,MATCH(LARGE(Calc!$Q$15:$Q$24,3),Calc!$Q$15:$Q$24,0)) -> 0.38235294 | Q12: =INDEX(Calc!$P$15:$P$24,MATCH(LARGE(Calc!$Q$15:$Q$24,3),Calc!$Q$15:$Q$24,0)) -> 0.4166407 | R12: =INDEX(Calc!$O$15:$O$24,MATCH(LARGE(Calc!$Q$15:$Q$24,3),Calc!$Q$15:$Q$24,0)) -> 1337
B13: =INDEX(Calc!$A$3:$A$11,MATCH(SMALL(Calc!$H$3:$H$11,4),Calc!$H$3:$H$11,0)) -> ISD Urban | C13: =INDEX(Calc!$B$3:$B$11,MATCH(SMALL(Calc!$H$3:$H$11,4),Calc!$H$3:$H$11,0)) -> 730 | D13: =INDEX(Calc!$C$3:$C$11,MATCH(SMALL(Calc!$H$3:$H$11,4),Calc!$H$3:$H$11,0)) -> 350 | E13: =INDEX(Calc!$D$3:$D$11,MATCH(SMALL(Calc!$H$3:$H$11,4),Calc!$H$3:$H$11,0)) -> 380 | F13: =INDEX(Calc!$G$3:$G$11,MATCH(SMALL(Calc!$H$3:$H$11,4),Calc!$H$3:$H$11,0)) -> 0.47945205 | G13: =INDEX(Calc!$F$3:$F$11,MATCH(SMALL(Calc!$H$3:$H$11,4),Calc!$H$3:$H$11,0)) -> 0 | I13: 4 | J13: =INDEX(Calc!$A$15:$A$24,MATCH(LARGE(Calc!$Q$15:$Q$24,4),Calc!$Q$15:$Q$24,0)) -> Bhuvanagiri | K13: =INDEX(Calc!$R$15:$R$24,MATCH(LARGE(Calc!$Q$15:$Q$24,4),Calc!$Q$15:$Q$24,0)) -> 0.7443609 | L13: =INDEX(Calc!$S$15:$S$24,MATCH(LARGE(Calc!$Q$15:$Q$24,4),Calc!$Q$15:$Q$24,0)) -> 0.75443787 | M13: =INDEX(Calc!$T$15:$T$24,MATCH(LARGE(Calc!$Q$15:$Q$24,4),Calc!$Q$15:$Q$24,0)) -> 0.52265372 | N13: =INDEX(Calc!$U$15:$U$24,MATCH(LARGE(Calc!$Q$15:$Q$24,4),Calc!$Q$15:$Q$24,0)) -> 0.52702703 | O13: =INDEX(Calc!$V$15:$V$24,MATCH(LARGE(Calc!$Q$15:$Q$24,4),Calc!$Q$15:$Q$24,0)) -> 0.41312741 | P13: =INDEX(Calc!$W$15:$W$24,MATCH(LARGE(Calc!$Q$15:$Q$24,4),Calc!$Q$15:$Q$24,0)) -> 0.37288136 | Q13: =INDEX(Calc!$P$15:$P$24,MATCH(LARGE(Calc!$Q$15:$Q$24,4),Calc!$Q$15:$Q$24,0)) -> 0.4109972 | R13: =INDEX(Calc!$O$15:$O$24,MATCH(LARGE(Calc!$Q$15:$Q$24,4),Calc!$Q$15:$Q$24,0)) -> 882
B14: =INDEX(Calc!$A$3:$A$11,MATCH(SMALL(Calc!$H$3:$H$11,5),Calc!$H$3:$H$11,0)) -> ISD Natham | C14: =INDEX(Calc!$B$3:$B$11,MATCH(SMALL(Calc!$H$3:$H$11,5),Calc!$H$3:$H$11,0)) -> 1690 | D14: =INDEX(Calc!$C$3:$C$11,MATCH(SMALL(Calc!$H$3:$H$11,5),Calc!$H$3:$H$11,0)) -> 883 | E14: =INDEX(Calc!$D$3:$D$11,MATCH(SMALL(Calc!$H$3:$H$11,5),Calc!$H$3:$H$11,0)) -> 807 | F14: =INDEX(Calc!$G$3:$G$11,MATCH(SMALL(Calc!$H$3:$H$11,5),Calc!$H$3:$H$11,0)) -> 0.52248521 | G14: =INDEX(Calc!$F$3:$F$11,MATCH(SMALL(Calc!$H$3:$H$11,5),Calc!$H$3:$H$11,0)) -> 0 | I14: 5 | J14: =INDEX(Calc!$A$15:$A$24,MATCH(LARGE(Calc!$Q$15:$Q$24,5),Calc!$Q$15:$Q$24,0)) -> Kurinjipadi | K14: =INDEX(Calc!$R$15:$R$24,MATCH(LARGE(Calc!$Q$15:$Q$24,5),Calc!$Q$15:$Q$24,0)) -> 0.73653566 | L14: =INDEX(Calc!$S$15:$S$24,MATCH(LARGE(Calc!$Q$15:$Q$24,5),Calc!$Q$15:$Q$24,0)) -> 0.79253112 | M14: =INDEX(Calc!$T$15:$T$24,MATCH(LARGE(Calc!$Q$15:$Q$24,5),Calc!$Q$15:$Q$24,0)) -> 0.54934211 | N14: =INDEX(Calc!$U$15:$U$24,MATCH(LARGE(Calc!$Q$15:$Q$24,5),Calc!$Q$15:$Q$24,0)) -> 0.64571429 | O14: =INDEX(Calc!$V$15:$V$24,MATCH(LARGE(Calc!$Q$15:$Q$24,5),Calc!$Q$15:$Q$24,0)) -> 0.37677054 | P14: =INDEX(Calc!$W$15:$W$24,MATCH(LARGE(Calc!$Q$15:$Q$24,5),Calc!$Q$15:$Q$24,0)) -> 0.36363636 | Q14: =INDEX(Calc!$P$15:$P$24,MATCH(LARGE(Calc!$Q$15:$Q$24,5),Calc!$Q$15:$Q$24,0)) -> 0.40523394 | R14: =INDEX(Calc!$O$15:$O$24,MATCH(LARGE(Calc!$Q$15:$Q$24,5),Calc!$Q$15:$Q$24,0)) -> 1022
B15: =INDEX(Calc!$A$3:$A$11,MATCH(SMALL(Calc!$H$3:$H$11,6),Calc!$H$3:$H$11,0)) -> ISD Rural | C15: =INDEX(Calc!$B$3:$B$11,MATCH(SMALL(Calc!$H$3:$H$11,6),Calc!$H$3:$H$11,0)) -> 7385 | D15: =INDEX(Calc!$C$3:$C$11,MATCH(SMALL(Calc!$H$3:$H$11,6),Calc!$H$3:$H$11,0)) -> 3947 | E15: =INDEX(Calc!$D$3:$D$11,MATCH(SMALL(Calc!$H$3:$H$11,6),Calc!$H$3:$H$11,0)) -> 3438 | F15: =INDEX(Calc!$G$3:$G$11,MATCH(SMALL(Calc!$H$3:$H$11,6),Calc!$H$3:$H$11,0)) -> 0.53446175 | G15: =INDEX(Calc!$F$3:$F$11,MATCH(SMALL(Calc!$H$3:$H$11,6),Calc!$H$3:$H$11,0)) -> 37 | I15: 6 | J15: =INDEX(Calc!$A$15:$A$24,MATCH(LARGE(Calc!$Q$15:$Q$24,6),Calc!$Q$15:$Q$24,0)) -> Vridhachalam | K15: =INDEX(Calc!$R$15:$R$24,MATCH(LARGE(Calc!$Q$15:$Q$24,6),Calc!$Q$15:$Q$24,0)) -> 0.96945551 | L15: =INDEX(Calc!$S$15:$S$24,MATCH(LARGE(Calc!$Q$15:$Q$24,6),Calc!$Q$15:$Q$24,0)) -> 0.64878049 | M15: =INDEX(Calc!$T$15:$T$24,MATCH(LARGE(Calc!$Q$15:$Q$24,6),Calc!$Q$15:$Q$24,0)) -> 0.5132336 | N15: =INDEX(Calc!$U$15:$U$24,MATCH(LARGE(Calc!$Q$15:$Q$24,6),Calc!$Q$15:$Q$24,0)) -> 0.5 | O15: =INDEX(Calc!$V$15:$V$24,MATCH(LARGE(Calc!$Q$15:$Q$24,6),Calc!$Q$15:$Q$24,0)) -> 0.36988848 | P15: =INDEX(Calc!$W$15:$W$24,MATCH(LARGE(Calc!$Q$15:$Q$24,6),Calc!$Q$15:$Q$24,0)) -> 0.33617021 | Q15: =INDEX(Calc!$P$15:$P$24,MATCH(LARGE(Calc!$Q$15:$Q$24,6),Calc!$Q$15:$Q$24,0)) -> 0.39524909 | R15: =INDEX(Calc!$O$15:$O$24,MATCH(LARGE(Calc!$Q$15:$Q$24,6),Calc!$Q$15:$Q$24,0)) -> 1198
B16: =INDEX(Calc!$A$3:$A$11,MATCH(SMALL(Calc!$H$3:$H$11,7),Calc!$H$3:$H$11,0)) -> NISD Natham | C16: =INDEX(Calc!$B$3:$B$11,MATCH(SMALL(Calc!$H$3:$H$11,7),Calc!$H$3:$H$11,0)) -> 2871 | D16: =INDEX(Calc!$C$3:$C$11,MATCH(SMALL(Calc!$H$3:$H$11,7),Calc!$H$3:$H$11,0)) -> 2123 | E16: =INDEX(Calc!$D$3:$D$11,MATCH(SMALL(Calc!$H$3:$H$11,7),Calc!$H$3:$H$11,0)) -> 748 | F16: =INDEX(Calc!$G$3:$G$11,MATCH(SMALL(Calc!$H$3:$H$11,7),Calc!$H$3:$H$11,0)) -> 0.7394636 | G16: =INDEX(Calc!$F$3:$F$11,MATCH(SMALL(Calc!$H$3:$H$11,7),Calc!$H$3:$H$11,0)) -> 0 | I16: 7 | J16: =INDEX(Calc!$A$15:$A$24,MATCH(LARGE(Calc!$Q$15:$Q$24,7),Calc!$Q$15:$Q$24,0)) -> Chidambaram | K16: =INDEX(Calc!$R$15:$R$24,MATCH(LARGE(Calc!$Q$15:$Q$24,7),Calc!$Q$15:$Q$24,0)) -> 0.76793893 | L16: =INDEX(Calc!$S$15:$S$24,MATCH(LARGE(Calc!$Q$15:$Q$24,7),Calc!$Q$15:$Q$24,0)) -> 0.7318612 | M16: =INDEX(Calc!$T$15:$T$24,MATCH(LARGE(Calc!$Q$15:$Q$24,7),Calc!$Q$15:$Q$24,0)) -> 0.55424528 | N16: =INDEX(Calc!$U$15:$U$24,MATCH(LARGE(Calc!$Q$15:$Q$24,7),Calc!$Q$15:$Q$24,0)) -> 0.4619883 | O16: =INDEX(Calc!$V$15:$V$24,MATCH(LARGE(Calc!$Q$15:$Q$24,7),Calc!$Q$15:$Q$24,0)) -> 0.432 | P16: =INDEX(Calc!$W$15:$W$24,MATCH(LARGE(Calc!$Q$15:$Q$24,7),Calc!$Q$15:$Q$24,0)) -> 0.37142857 | Q16: =INDEX(Calc!$P$15:$P$24,MATCH(LARGE(Calc!$Q$15:$Q$24,7),Calc!$Q$15:$Q$24,0)) -> 0.39353213 | R16: =INDEX(Calc!$O$15:$O$24,MATCH(LARGE(Calc!$Q$15:$Q$24,7),Calc!$Q$15:$Q$24,0)) -> 937
B17: =INDEX(Calc!$A$3:$A$11,MATCH(SMALL(Calc!$H$3:$H$11,8),Calc!$H$3:$H$11,0)) -> NISD Urban | C17: =INDEX(Calc!$B$3:$B$11,MATCH(SMALL(Calc!$H$3:$H$11,8),Calc!$H$3:$H$11,0)) -> 1024 | D17: =INDEX(Calc!$C$3:$C$11,MATCH(SMALL(Calc!$H$3:$H$11,8),Calc!$H$3:$H$11,0)) -> 801 | E17: =INDEX(Calc!$D$3:$D$11,MATCH(SMALL(Calc!$H$3:$H$11,8),Calc!$H$3:$H$11,0)) -> 223 | F17: =INDEX(Calc!$G$3:$G$11,MATCH(SMALL(Calc!$H$3:$H$11,8),Calc!$H$3:$H$11,0)) -> 0.78222656 | G17: =INDEX(Calc!$F$3:$F$11,MATCH(SMALL(Calc!$H$3:$H$11,8),Calc!$H$3:$H$11,0)) -> 0 | I17: 8 | J17: =INDEX(Calc!$A$15:$A$24,MATCH(LARGE(Calc!$Q$15:$Q$24,8),Calc!$Q$15:$Q$24,0)) -> Titagudi | K17: =INDEX(Calc!$R$15:$R$24,MATCH(LARGE(Calc!$Q$15:$Q$24,8),Calc!$Q$15:$Q$24,0)) -> 0.81553398 | L17: =INDEX(Calc!$S$15:$S$24,MATCH(LARGE(Calc!$Q$15:$Q$24,8),Calc!$Q$15:$Q$24,0)) -> 0.79886686 | M17: =INDEX(Calc!$T$15:$T$24,MATCH(LARGE(Calc!$Q$15:$Q$24,8),Calc!$Q$15:$Q$24,0)) -> 0.4686907 | N17: =INDEX(Calc!$U$15:$U$24,MATCH(LARGE(Calc!$Q$15:$Q$24,8),Calc!$Q$15:$Q$24,0)) -> 0.44805195 | O17: =INDEX(Calc!$V$15:$V$24,MATCH(LARGE(Calc!$Q$15:$Q$24,8),Calc!$Q$15:$Q$24,0)) -> 0.45247934 | P17: =INDEX(Calc!$W$15:$W$24,MATCH(LARGE(Calc!$Q$15:$Q$24,8),Calc!$Q$15:$Q$24,0)) -> 0.37073171 | Q17: =INDEX(Calc!$P$15:$P$24,MATCH(LARGE(Calc!$Q$15:$Q$24,8),Calc!$Q$15:$Q$24,0)) -> 0.38555163 | R17: =INDEX(Calc!$O$15:$O$24,MATCH(LARGE(Calc!$Q$15:$Q$24,8),Calc!$Q$15:$Q$24,0)) -> 982
B18: =INDEX(Calc!$A$3:$A$11,MATCH(SMALL(Calc!$H$3:$H$11,9),Calc!$H$3:$H$11,0)) -> NISD Rural | C18: =INDEX(Calc!$B$3:$B$11,MATCH(SMALL(Calc!$H$3:$H$11,9),Calc!$H$3:$H$11,0)) -> 6738 | D18: =INDEX(Calc!$C$3:$C$11,MATCH(SMALL(Calc!$H$3:$H$11,9),Calc!$H$3:$H$11,0)) -> 5284 | E18: =INDEX(Calc!$D$3:$D$11,MATCH(SMALL(Calc!$H$3:$H$11,9),Calc!$H$3:$H$11,0)) -> 1454 | F18: =INDEX(Calc!$G$3:$G$11,MATCH(SMALL(Calc!$H$3:$H$11,9),Calc!$H$3:$H$11,0)) -> 0.78420896 | G18: =INDEX(Calc!$F$3:$F$11,MATCH(SMALL(Calc!$H$3:$H$11,9),Calc!$H$3:$H$11,0)) -> 10 | I18: 9 | J18: =INDEX(Calc!$A$15:$A$24,MATCH(LARGE(Calc!$Q$15:$Q$24,9),Calc!$Q$15:$Q$24,0)) -> Cuddalore | K18: =INDEX(Calc!$R$15:$R$24,MATCH(LARGE(Calc!$Q$15:$Q$24,9),Calc!$Q$15:$Q$24,0)) -> 0.75037594 | L18: =INDEX(Calc!$S$15:$S$24,MATCH(LARGE(Calc!$Q$15:$Q$24,9),Calc!$Q$15:$Q$24,0)) -> 0.72803347 | M18: =INDEX(Calc!$T$15:$T$24,MATCH(LARGE(Calc!$Q$15:$Q$24,9),Calc!$Q$15:$Q$24,0)) -> 0.62745098 | N18: =INDEX(Calc!$U$15:$U$24,MATCH(LARGE(Calc!$Q$15:$Q$24,9),Calc!$Q$15:$Q$24,0)) -> 0.52095808 | O18: =INDEX(Calc!$V$15:$V$24,MATCH(LARGE(Calc!$Q$15:$Q$24,9),Calc!$Q$15:$Q$24,0)) -> 0.34246575 | P18: =INDEX(Calc!$W$15:$W$24,MATCH(LARGE(Calc!$Q$15:$Q$24,9),Calc!$Q$15:$Q$24,0)) -> 0.42168675 | Q18: =INDEX(Calc!$P$15:$P$24,MATCH(LARGE(Calc!$Q$15:$Q$24,9),Calc!$Q$15:$Q$24,0)) -> 0.38430745 | R18: =INDEX(Calc!$O$15:$O$24,MATCH(LARGE(Calc!$Q$15:$Q$24,9),Calc!$Q$15:$Q$24,0)) -> 960
I19: 10 | J19: =INDEX(Calc!$A$15:$A$24,MATCH(LARGE(Calc!$Q$15:$Q$24,10),Calc!$Q$15:$Q$24,0)) -> Veppur | K19: =INDEX(Calc!$R$15:$R$24,MATCH(LARGE(Calc!$Q$15:$Q$24,10),Calc!$Q$15:$Q$24,0)) -> 0.74965422 | L19: =INDEX(Calc!$S$15:$S$24,MATCH(LARGE(Calc!$Q$15:$Q$24,10),Calc!$Q$15:$Q$24,0)) -> 0.76651982 | M19: =INDEX(Calc!$T$15:$T$24,MATCH(LARGE(Calc!$Q$15:$Q$24,10),Calc!$Q$15:$Q$24,0)) -> 0.50971599 | N19: =INDEX(Calc!$U$15:$U$24,MATCH(LARGE(Calc!$Q$15:$Q$24,10),Calc!$Q$15:$Q$24,0)) -> 0.66666667 | O19: =INDEX(Calc!$V$15:$V$24,MATCH(LARGE(Calc!$Q$15:$Q$24,10),Calc!$Q$15:$Q$24,0)) -> 0.464 | P19: =INDEX(Calc!$W$15:$W$24,MATCH(LARGE(Calc!$Q$15:$Q$24,10),Calc!$Q$15:$Q$24,0)) -> 0.42391304 | Q19: =INDEX(Calc!$P$15:$P$24,MATCH(LARGE(Calc!$Q$15:$Q$24,10),Calc!$Q$15:$Q$24,0)) -> 0.37927711 | R19: =INDEX(Calc!$O$15:$O$24,MATCH(LARGE(Calc!$Q$15:$Q$24,10),Calc!$Q$15:$Q$24,0)) -> 787
J20: District | K20: =Calc!R25 -> 0.78420896 | L20: =Calc!S25 -> 0.7394636 | M20: =Calc!T25 -> 0.53446175 | N20: =Calc!U25 -> 0.52248521 | O20: =Calc!V25 -> 0.3925117 | P20: =Calc!W25 -> 0.37319975 | Q20: =Calc!P25 -> 0.40002555 | R20: =Calc!O25 -> 9395
I21: Colour: green = 75% or more disposed, amber = 50 to 75%, red = below 50%. Pending %: green up to 25%, amber to 50%, red above.
B23: 3. Surveyor disposal: September vs August (by taluk) | I23: 4. Pending within vs beyond time limit | O23: 5. Top rejection villages
B24: Taluk | C24: Sep-26 | D24: Aug-26 | E24: Change | F24: Change % | J24: Stream | K24: Pending | L24: Within limit | M24: Beyond limit | O24: Category ▸ | P24: NISD Rural | T24: =MATCH(P24,{"NISD Rural","NISD Natham","ISD Rural","ISD Natham"},0) -> 1
B25: =INDEX(Calc!$A$30:$A$39,MATCH(LARGE(Calc!$D$30:$D$39,1),Calc!$D$30:$D$39,0)) -> Panruti | C25: =INDEX(Calc!$B$30:$B$39,MATCH(LARGE(Calc!$D$30:$D$39,1),Calc!$D$30:$D$39,0)) -> 1254 | D25: =INDEX(Calc!$C$30:$C$39,MATCH(LARGE(Calc!$D$30:$D$39,1),Calc!$D$30:$D$39,0)) -> 1300 | E25: =C25-D25 -> -46 | F25: =IFERROR(E25/D25,0) -> -0.035384615 | I25: 1 | J25: =INDEX(Calc!$A$3:$A$11,MATCH(LARGE(Calc!$I$3:$I$11,1),Calc!$I$3:$I$11,0)) -> ISD Rural | K25: =INDEX(Calc!$D$3:$D$11,MATCH(LARGE(Calc!$I$3:$I$11,1),Calc!$I$3:$I$11,0)) -> 3438 | L25: =INDEX(Calc!$E$3:$E$11,MATCH(LARGE(Calc!$I$3:$I$11,1),Calc!$I$3:$I$11,0)) -> 3401 | M25: =INDEX(Calc!$F$3:$F$11,MATCH(LARGE(Calc!$I$3:$I$11,1),Calc!$I$3:$I$11,0)) -> 37 | O25: Village | Q25: Taluk | R25: Rejections
B26: =INDEX(Calc!$A$30:$A$39,MATCH(LARGE(Calc!$D$30:$D$39,2),Calc!$D$30:$D$39,0)) -> Cuddalore | C26: =INDEX(Calc!$B$30:$B$39,MATCH(LARGE(Calc!$D$30:$D$39,2),Calc!$D$30:$D$39,0)) -> 1149 | D26: =INDEX(Calc!$C$30:$C$39,MATCH(LARGE(Calc!$D$30:$D$39,2),Calc!$D$30:$D$39,0)) -> 1165 | E26: =C26-D26 -> -16 | F26: =IFERROR(E26/D26,0) -> -0.013733906 | I26: 2 | J26: =INDEX(Calc!$A$3:$A$11,MATCH(LARGE(Calc!$I$3:$I$11,2),Calc!$I$3:$I$11,0)) -> F-Line Rural | K26: =INDEX(Calc!$D$3:$D$11,MATCH(LARGE(Calc!$I$3:$I$11,2),Calc!$I$3:$I$11,0)) -> 1947 | L26: =INDEX(Calc!$E$3:$E$11,MATCH(LARGE(Calc!$I$3:$I$11,2),Calc!$I$3:$I$11,0)) -> 942 | M26: =INDEX(Calc!$F$3:$F$11,MATCH(LARGE(Calc!$I$3:$I$11,2),Calc!$I$3:$I$11,0)) -> 1005 | O26: ="1. "&PROPER(INDEX(Calc!$V$44:$V$93,MATCH(LARGE(Calc!$X$44:$X$93,1),Calc!$X$44:$X$93,0))) -> 1. Vegakollai | Q26: =PROPER(INDEX(Calc!$U$44:$U$93,MATCH(LARGE(Calc!$X$44:$X$93,1),Calc!$X$44:$X$93,0))) -> Panruti | R26: =INDEX(Calc!$W$44:$W$93,MATCH(LARGE(Calc!$X$44:$X$93,1),Calc!$X$44:$X$93,0)) -> 21
B27: =INDEX(Calc!$A$30:$A$39,MATCH(LARGE(Calc!$D$30:$D$39,3),Calc!$D$30:$D$39,0)) -> Virudhachalam | C27: =INDEX(Calc!$B$30:$B$39,MATCH(LARGE(Calc!$D$30:$D$39,3),Calc!$D$30:$D$39,0)) -> 1108 | D27: =INDEX(Calc!$C$30:$C$39,MATCH(LARGE(Calc!$D$30:$D$39,3),Calc!$D$30:$D$39,0)) -> 1188 | E27: =C27-D27 -> -80 | F27: =IFERROR(E27/D27,0) -> -0.067340067 | I27: 3 | J27: =INDEX(Calc!$A$3:$A$11,MATCH(LARGE(Calc!$I$3:$I$11,3),Calc!$I$3:$I$11,0)) -> NISD Rural | K27: =INDEX(Calc!$D$3:$D$11,MATCH(LARGE(Calc!$I$3:$I$11,3),Calc!$I$3:$I$11,0)) -> 1454 | L27: =INDEX(Calc!$E$3:$E$11,MATCH(LARGE(Calc!$I$3:$I$11,3),Calc!$I$3:$I$11,0)) -> 1444 | M27: =INDEX(Calc!$F$3:$F$11,MATCH(LARGE(Calc!$I$3:$I$11,3),Calc!$I$3:$I$11,0)) -> 10 | O27: ="2. "&PROPER(INDEX(Calc!$V$44:$V$93,MATCH(LARGE(Calc!$X$44:$X$93,2),Calc!$X$44:$X$93,0))) -> 2. Vallam | Q27: =PROPER(INDEX(Calc!$U$44:$U$93,MATCH(LARGE(Calc!$X$44:$X$93,2),Calc!$X$44:$X$93,0))) -> Panruti | R27: =INDEX(Calc!$W$44:$W$93,MATCH(LARGE(Calc!$X$44:$X$93,2),Calc!$X$44:$X$93,0)) -> 14
B28: =INDEX(Calc!$A$30:$A$39,MATCH(LARGE(Calc!$D$30:$D$39,4),Calc!$D$30:$D$39,0)) -> Kurinjipadi | C28: =INDEX(Calc!$B$30:$B$39,MATCH(LARGE(Calc!$D$30:$D$39,4),Calc!$D$30:$D$39,0)) -> 755 | D28: =INDEX(Calc!$C$30:$C$39,MATCH(LARGE(Calc!$D$30:$D$39,4),Calc!$D$30:$D$39,0)) -> 921 | E28: =C28-D28 -> -166 | F28: =IFERROR(E28/D28,0) -> -0.18023887 | I28: 4 | J28: =INDEX(Calc!$A$3:$A$11,MATCH(LARGE(Calc!$I$3:$I$11,4),Calc!$I$3:$I$11,0)) -> F-Line Natham | K28: =INDEX(Calc!$D$3:$D$11,MATCH(LARGE(Calc!$I$3:$I$11,4),Calc!$I$3:$I$11,0)) -> 1001 | L28: =INDEX(Calc!$E$3:$E$11,MATCH(LARGE(Calc!$I$3:$I$11,4),Calc!$I$3:$I$11,0)) -> 529 | M28: =INDEX(Calc!$F$3:$F$11,MATCH(LARGE(Calc!$I$3:$I$11,4),Calc!$I$3:$I$11,0)) -> 472 | O28: ="3. "&PROPER(INDEX(Calc!$V$44:$V$93,MATCH(LARGE(Calc!$X$44:$X$93,3),Calc!$X$44:$X$93,0))) -> 3. Vadakuthu | Q28: =PROPER(INDEX(Calc!$U$44:$U$93,MATCH(LARGE(Calc!$X$44:$X$93,3),Calc!$X$44:$X$93,0))) -> Kurinjipadi | R28: =INDEX(Calc!$W$44:$W$93,MATCH(LARGE(Calc!$X$44:$X$93,3),Calc!$X$44:$X$93,0)) -> 10
B29: =INDEX(Calc!$A$30:$A$39,MATCH(LARGE(Calc!$D$30:$D$39,5),Calc!$D$30:$D$39,0)) -> Chidambaram | C29: =INDEX(Calc!$B$30:$B$39,MATCH(LARGE(Calc!$D$30:$D$39,5),Calc!$D$30:$D$39,0)) -> 678 | D29: =INDEX(Calc!$C$30:$C$39,MATCH(LARGE(Calc!$D$30:$D$39,5),Calc!$D$30:$D$39,0)) -> 823 | E29: =C29-D29 -> -145 | F29: =IFERROR(E29/D29,0) -> -0.17618469 | I29: 5 | J29: =INDEX(Calc!$A$3:$A$11,MATCH(LARGE(Calc!$I$3:$I$11,5),Calc!$I$3:$I$11,0)) -> ISD Natham | K29: =INDEX(Calc!$D$3:$D$11,MATCH(LARGE(Calc!$I$3:$I$11,5),Calc!$I$3:$I$11,0)) -> 807 | L29: =INDEX(Calc!$E$3:$E$11,MATCH(LARGE(Calc!$I$3:$I$11,5),Calc!$I$3:$I$11,0)) -> 807 | M29: =INDEX(Calc!$F$3:$F$11,MATCH(LARGE(Calc!$I$3:$I$11,5),Calc!$I$3:$I$11,0)) -> 0 | O29: ="4. "&PROPER(INDEX(Calc!$V$44:$V$93,MATCH(LARGE(Calc!$X$44:$X$93,4),Calc!$X$44:$X$93,0))) -> 4. Melmampattu | Q29: =PROPER(INDEX(Calc!$U$44:$U$93,MATCH(LARGE(Calc!$X$44:$X$93,4),Calc!$X$44:$X$93,0))) -> Panruti | R29: =INDEX(Calc!$W$44:$W$93,MATCH(LARGE(Calc!$X$44:$X$93,4),Calc!$X$44:$X$93,0)) -> 9
B30: =INDEX(Calc!$A$30:$A$39,MATCH(LARGE(Calc!$D$30:$D$39,6),Calc!$D$30:$D$39,0)) -> Bhuvanagiri | C30: =INDEX(Calc!$B$30:$B$39,MATCH(LARGE(Calc!$D$30:$D$39,6),Calc!$D$30:$D$39,0)) -> 537 | D30: =INDEX(Calc!$C$30:$C$39,MATCH(LARGE(Calc!$D$30:$D$39,6),Calc!$D$30:$D$39,0)) -> 686 | E30: =C30-D30 -> -149 | F30: =IFERROR(E30/D30,0) -> -0.21720117 | I30: 6 | J30: =INDEX(Calc!$A$3:$A$11,MATCH(LARGE(Calc!$I$3:$I$11,6),Calc!$I$3:$I$11,0)) -> NISD Natham | K30: =INDEX(Calc!$D$3:$D$11,MATCH(LARGE(Calc!$I$3:$I$11,6),Calc!$I$3:$I$11,0)) -> 748 | L30: =INDEX(Calc!$E$3:$E$11,MATCH(LARGE(Calc!$I$3:$I$11,6),Calc!$I$3:$I$11,0)) -> 748 | M30: =INDEX(Calc!$F$3:$F$11,MATCH(LARGE(Calc!$I$3:$I$11,6),Calc!$I$3:$I$11,0)) -> 0 | O30: ="5. "&PROPER(INDEX(Calc!$V$44:$V$93,MATCH(LARGE(Calc!$X$44:$X$93,5),Calc!$X$44:$X$93,0))) -> 5. Parvathipuram | Q30: =PROPER(INDEX(Calc!$U$44:$U$93,MATCH(LARGE(Calc!$X$44:$X$93,5),Calc!$X$44:$X$93,0))) -> Kurinjipadi | R30: =INDEX(Calc!$W$44:$W$93,MATCH(LARGE(Calc!$X$44:$X$93,5),Calc!$X$44:$X$93,0)) -> 9
B31: =INDEX(Calc!$A$30:$A$39,MATCH(LARGE(Calc!$D$30:$D$39,7),Calc!$D$30:$D$39,0)) -> Veppur | C31: =INDEX(Calc!$B$30:$B$39,MATCH(LARGE(Calc!$D$30:$D$39,7),Calc!$D$30:$D$39,0)) -> 509 | D31: =INDEX(Calc!$C$30:$C$39,MATCH(LARGE(Calc!$D$30:$D$39,7),Calc!$D$30:$D$39,0)) -> 621 | E31: =C31-D31 -> -112 | F31: =IFERROR(E31/D31,0) -> -0.18035427 | I31: 7 | J31: =INDEX(Calc!$A$3:$A$11,MATCH(LARGE(Calc!$I$3:$I$11,7),Calc!$I$3:$I$11,0)) -> ISD Urban | K31: =INDEX(Calc!$D$3:$D$11,MATCH(LARGE(Calc!$I$3:$I$11,7),Calc!$I$3:$I$11,0)) -> 380 | L31: =INDEX(Calc!$E$3:$E$11,MATCH(LARGE(Calc!$I$3:$I$11,7),Calc!$I$3:$I$11,0)) -> 380 | M31: =INDEX(Calc!$F$3:$F$11,MATCH(LARGE(Calc!$I$3:$I$11,7),Calc!$I$3:$I$11,0)) -> 0 | O31: ="6. "&PROPER(INDEX(Calc!$V$44:$V$93,MATCH(LARGE(Calc!$X$44:$X$93,6),Calc!$X$44:$X$93,0))) -> 6. Marungur | Q31: =PROPER(INDEX(Calc!$U$44:$U$93,MATCH(LARGE(Calc!$X$44:$X$93,6),Calc!$X$44:$X$93,0))) -> Panruti | R31: =INDEX(Calc!$W$44:$W$93,MATCH(LARGE(Calc!$X$44:$X$93,6),Calc!$X$44:$X$93,0)) -> 8
B32: =INDEX(Calc!$A$30:$A$39,MATCH(LARGE(Calc!$D$30:$D$39,8),Calc!$D$30:$D$39,0)) -> Titakudi | C32: =INDEX(Calc!$B$30:$B$39,MATCH(LARGE(Calc!$D$30:$D$39,8),Calc!$D$30:$D$39,0)) -> 485 | D32: =INDEX(Calc!$C$30:$C$39,MATCH(LARGE(Calc!$D$30:$D$39,8),Calc!$D$30:$D$39,0)) -> 576 | E32: =C32-D32 -> -91 | F32: =IFERROR(E32/D32,0) -> -0.15798611 | I32: 8 | J32: =INDEX(Calc!$A$3:$A$11,MATCH(LARGE(Calc!$I$3:$I$11,8),Calc!$I$3:$I$11,0)) -> NISD Urban | K32: =INDEX(Calc!$D$3:$D$11,MATCH(LARGE(Calc!$I$3:$I$11,8),Calc!$I$3:$I$11,0)) -> 223 | L32: =INDEX(Calc!$E$3:$E$11,MATCH(LARGE(Calc!$I$3:$I$11,8),Calc!$I$3:$I$11,0)) -> 223 | M32: =INDEX(Calc!$F$3:$F$11,MATCH(LARGE(Calc!$I$3:$I$11,8),Calc!$I$3:$I$11,0)) -> 0 | O32: ="7. "&PROPER(INDEX(Calc!$V$44:$V$93,MATCH(LARGE(Calc!$X$44:$X$93,7),Calc!$X$44:$X$93,0))) -> 7. Keezhur | Q32: =PROPER(INDEX(Calc!$U$44:$U$93,MATCH(LARGE(Calc!$X$44:$X$93,7),Calc!$X$44:$X$93,0))) -> Kurinjipadi | R32: =INDEX(Calc!$W$44:$W$93,MATCH(LARGE(Calc!$X$44:$X$93,7),Calc!$X$44:$X$93,0)) -> 8
B33: =INDEX(Calc!$A$30:$A$39,MATCH(LARGE(Calc!$D$30:$D$39,9),Calc!$D$30:$D$39,0)) -> Kattumannarkoil | C33: =INDEX(Calc!$B$30:$B$39,MATCH(LARGE(Calc!$D$30:$D$39,9),Calc!$D$30:$D$39,0)) -> 434 | D33: =INDEX(Calc!$C$30:$C$39,MATCH(LARGE(Calc!$D$30:$D$39,9),Calc!$D$30:$D$39,0)) -> 612 | E33: =C33-D33 -> -178 | F33: =IFERROR(E33/D33,0) -> -0.29084967 | I33: 9 | J33: =INDEX(Calc!$A$3:$A$11,MATCH(LARGE(Calc!$I$3:$I$11,9),Calc!$I$3:$I$11,0)) -> F-Line Urban | K33: =INDEX(Calc!$D$3:$D$11,MATCH(LARGE(Calc!$I$3:$I$11,9),Calc!$I$3:$I$11,0)) -> 118 | L33: =INDEX(Calc!$E$3:$E$11,MATCH(LARGE(Calc!$I$3:$I$11,9),Calc!$I$3:$I$11,0)) -> 78 | M33: =INDEX(Calc!$F$3:$F$11,MATCH(LARGE(Calc!$I$3:$I$11,9),Calc!$I$3:$I$11,0)) -> 40 | O33: ="8. "&PROPER(INDEX(Calc!$V$44:$V$93,MATCH(LARGE(Calc!$X$44:$X$93,8),Calc!$X$44:$X$93,0))) -> 8. Pinnalur | Q33: =PROPER(INDEX(Calc!$U$44:$U$93,MATCH(LARGE(Calc!$X$44:$X$93,8),Calc!$X$44:$X$93,0))) -> Bhuvanagiri | R33: =INDEX(Calc!$W$44:$W$93,MATCH(LARGE(Calc!$X$44:$X$93,8),Calc!$X$44:$X$93,0)) -> 7
B34: =INDEX(Calc!$A$30:$A$39,MATCH(LARGE(Calc!$D$30:$D$39,10),Calc!$D$30:$D$39,0)) -> Srimushnam | C34: =INDEX(Calc!$B$30:$B$39,MATCH(LARGE(Calc!$D$30:$D$39,10),Calc!$D$30:$D$39,0)) -> 243 | D34: =INDEX(Calc!$C$30:$C$39,MATCH(LARGE(Calc!$D$30:$D$39,10),Calc!$D$30:$D$39,0)) -> 327 | E34: =C34-D34 -> -84 | F34: =IFERROR(E34/D34,0) -> -0.25688073
B35: District total | C35: =SUM(C25:C34) -> 7152 | D35: =SUM(D25:D34) -> 8219 | E35: =C35-D35 -> -1067 | F35: =IFERROR(E35/D35,0) -> -0.12982115
B37: Key points (update automatically)
B38: ="• District handled "&TEXT(B5,"#,##0")&" applications: "&TEXT(SUM(Calc!C3:C11),"#,##0")&" disposed ("&TEXT(E5,"0%")&"), "&TEXT(J5,"#,##0")&" pending." -> • District handled 25,422 applications: 15,306 disposed (60%), 10,116 pending.
B39: ="• Lowest disposal: "&B10&" "&TEXT(F10,"0%")&", "&B11&" "&TEXT(F11,"0%")&". Best: "&B18&" "&TEXT(F18,"0%")&"." -> • Lowest disposal: F-Line Urban 35%, F-Line Natham 37%. Best: NISD Rural 78%.
B40: ="• "&TEXT(N5,"#,##0")&" pending applications are beyond the time limit; "&TEXT(Calc!F9+Calc!F10+Calc!F11,"#,##0")&" of them are F-Line." -> • 1,564 pending applications are beyond the time limit; 1,517 of them are F-Line.
B41: ="• Highest pending share: "&J10&" ("&TEXT(Q10,"0%")&" of its applications); district average "&TEXT(Q20,"0%")&"." -> • Highest pending share: Kattumannarkoil (42% of its applications); district average 40%.
B42: ="• Surveyor disposal: "&TEXT(D35,"#,##0")&" (Aug) to "&TEXT(C35,"#,##0")&" (Sep), "&TEXT(F35,"+0%;-0%")&"." -> • Surveyor disposal: 8,219 (Aug) to 7,152 (Sep), -13%.
B43: ="• Data checks: "&Checks!D15&" (see the Checks sheet)." -> • Data checks: 1 issue(s) (see the Checks sheet).

Sheet How it works
B1: HOW THIS WORKBOOK WORKS
B2: DRA Meeting, Cuddalore District. You type the figures in the blue cells; every total, percentage, average, check and the whole Dashboard is calculated by formulas.
B4: 1. Colours: what you can change
B5: Colour | C5: Meaning | D5: Example | E5: What to do
B6: Blue text | C6: Typed data (input) | D6: Opening balance, Received, Approved, Rejected, pending breakup, surveyor disposals | E6: Type or change these figures.
B7: Black text | C7: Formula (calculated) | D7: Total, %, Disposed, Pending, Total rows, Averages, everything on the Dashboard | E7: Do not type over them. They update by themselves.
B8: Green text | C8: Figure pulled from another sheet | D8: ISD VAO sheet district columns, abstract, Calc sheet | E8: Do not type over them.
B9: Yellow cell | C9: Choice on the Dashboard | D9: Dashboard cell P24 (top rejection villages) | E9: Pick a category from the drop-down list.
B10: Red / pink cell | C10: A problem or an overdue figure | D10: Check column not 0; pending beyond the time limit | E10: Red check = fix the typed figures. Red overdue = needs follow-up.
B12: 2. What each sheet does
B13: Sheet | C13: What it holds | D13: You type (blue) | E13: Calculated automatically (black)
B14: Dashboard | C14: One-page summary of everything, with 4 charts | D14: Only the category drop-down (P24) | E14: Headline figures, stream table, taluk heat table, Sep vs Aug, ageing, top villages, key points, charts
B15: How it works | C15: This guide | D15: — | E15: —
B16: NISD RURAL, NISD NATHAM, URBAN NISD | C16: Not Involving Subdivision applications by taluk / town | D16: Opening, Received, Transferred (Natham), Approved, Rejected, pending breakup | E16: Total, %, Disposed, Pending, Pending beyond limit, Check, Total row
B17: ISD RURAL, ISD NATHAM, URBAN ISD | C17: Involving Subdivision applications by taluk / town | D17: Same as above | E17: Same as above
B18: ISD VAO &NATHAM | C18: ISD Rural disposal split between surveyor and VAO | D18: Surveyor approved / rejected, VAO approved / rejected | E18: District figures (pulled from ISD RURAL by taluk name), %, totals, Check
B19: RURAL FL, NATHAM FL, URBAN FL | C19: F-Line applications by taluk / town | D19: Opening, Received, Accepted, Rejected, pending breakup (up to 5 months) | E19: Total, %, Disposed, Pending, Pending beyond limit, Check, Total row
B20: 4 × TOP 5 VILLAGES sheets | C20: Top 5 rejection villages per taluk (NISD/ISD, Rural/Natham) | D20: Village names and rejection counts | E20: Nothing on the sheet; the Dashboard ranks them
B21: cud -div, cdm-div, vdm-div | C21: Surveyor-wise disposal for each taluk in the 3 divisions | D21: Name, designation, OPT Rural/Natham, FL Rural/Natham, Aug-26 total | E21: Sep-26 total, Change, Total row, Average row, No. of surveyors
B22: urban | C22: Urban surveyor-wise disposal | D22: Taluk, town, name, ISD / NISD / FL disposal, Aug-26 total | E22: Sep-26 total, Change, taluk subtotals
B23: abstract | C23: Surveyor performance by taluk, Sep vs Aug | D23: Nothing (taluk names only) | E23: Disposal = division Total row + urban surveyors of that taluk; averages; change
B24: Checks | C24: Confirms the typed figures agree with each other | D24: Nothing | E24: OK / CHECK for every sheet, total number of issues
B25: Calc | C25: Helper tables used by the Dashboard (grey tab) | D25: Taluk list A15:A24 only (if a new taluk is added) | E25: Stream totals, taluk totals, sort keys, village lists
B27: 3. The formulas
B28: Figure | C28: Formula used | D28: Example (as written in the sheet) | E28: Notes
B29: Total | C29: Opening + Received (Natham sheets: − Transferred) | D29: =C5+D5 | E29: Transferred is applications sent out, so it is subtracted.
B30: Disposed | C30: Approved + Rejected | D30: =F5+H5 | E30: Called Accepted in the F-Line sheets.
B31: Approved % / Rejected % | C31: Approved ÷ Disposed, Rejected ÷ Disposed | D31: =IFERROR(F5/J5,0) | E31: Shows 0% instead of an error if nothing is disposed. The two always add to 100%.
B32: Pending | C32: Total − Disposed | D32: =E5-J5 | E32: Never typed, so it can never disagree with Total and Disposed.
B33: Pending beyond limit | C33: Sum of every breakup column after the first | D33: =SUM(M5:N5) | E33: Limit: 15 days for NISD, 1 month for ISD and F-Line.
B34: Check | C34: Pending − sum of pending breakup | D34: =K5-SUM(L5:N5) | E34: Must be 0. Anything else turns red and is counted on the Checks sheet.
B35: Total row | C35: Sum from the first data row to the row just above the Total row | D35: =SUM(C5:INDEX(C:C,ROW()-1)) | E35: Any row you insert above Total is included automatically.
B36: Surveyor Sep-26 total | C36: OPT Rural + OPT Natham + FL Rural + FL Natham | D36: =SUM(E4:H4) (cud -div) | E36: Change = Sep-26 − Aug-26.
B37: Surveyor average | C37: Taluk total ÷ number of surveyors | D37: =IFERROR(I11/$L11,0) | E37: No. of surveyors is counted automatically from the name column.
B38: Abstract disposal | C38: Division Total row + urban surveyors with the same taluk name | D38: ='cud -div'!I11+SUMIF(urban!$B:$B,$B5,urban!$I:$I) | E38: Average = disposal ÷ (division surveyors + urban surveyors).
B40: 4. How the Dashboard works
B41: Part | C41: What it shows | D41: How it is calculated
B42: Headline figures | C42: Applications handled, % disposed, pending, pending beyond time limit | D42: Sum of the Total rows of all 9 application sheets (via the Calc sheet)
B43: 1. Disposal by stream | C43: The 9 streams (NISD / ISD / F-Line × Rural / Natham / Urban), worst first | D43: Disposed ÷ Total from each sheet's Total row; re-sorted automatically with SMALL / INDEX / MATCH. Blue bar = disposal %
B44: 2. Taluk heat table | C44: Disposal % for each taluk in each Rural / Natham stream; taluks ranked by pending % | D44: SUMIF by taluk name on each sheet. Green = 75% or more disposed, amber = 50 to 75%, red = below 50%. Pending %: green up to 25%, amber to 50%, red above
...

Sheet NISD RURAL
A1: NISD - RURAL REPORT WITH PERCENTAGE
A2: Periodicity:Date Range TRANSACTIONS FROM : 01-09-2026 - TO :30-09-2026 *
A3: S.No | B3: Taluk | C3: Opening balance as on 01.09.2026 | D3: Received | E3: Total | F3: Disposed | K3: Pending | L3: Pending breakup | O3: Pending beyond limit | P3: Check: pending − breakup (should be 0)
F4: Approved | G4: % | H4: Rejected | I4: % | J4: Total disposed | L4: Below 15 days | M4: Over 15 days | N4: Over 1 month
A5: 1 | B5: Bhuvanagiri | C5: 112 | D5: 420 | E5: =C5+D5 -> 532 | F5: 334 | G5: =IFERROR(F5/J5,0) -> 0.84343434 | H5: 62 | I5: =IFERROR(H5/J5,0) -> 0.15656566 | J5: =F5+H5 -> 396 | K5: =E5-J5 -> 136 | L5: 125 | M5: 0 | N5: 0 | O5: =SUM(M5:N5) -> 0 | P5: =K5-SUM(L5:N5) -> 11
A6: 2 | B6: Chidambaram | C6: 115 | D6: 540 | E6: =C6+D6 -> 655 | F6: 446 | G6: =IFERROR(F6/J6,0) -> 0.88667992 | H6: 57 | I6: =IFERROR(H6/J6,0) -> 0.11332008 | J6: =F6+H6 -> 503 | K6: =E6-J6 -> 152 | L6: 152 | M6: 0 | N6: 0 | O6: =SUM(M6:N6) -> 0 | P6: =K6-SUM(L6:N6) -> 0
A7: 3 | B7: Cuddalore | C7: 112 | D7: 553 | E7: =C7+D7 -> 665 | F7: 407 | G7: =IFERROR(F7/J7,0) -> 0.81563126 | H7: 92 | I7: =IFERROR(H7/J7,0) -> 0.18436874 | J7: =F7+H7 -> 499 | K7: =E7-J7 -> 166 | L7: 166 | M7: 0 | N7: 0 | O7: =SUM(M7:N7) -> 0 | P7: =K7-SUM(L7:N7) -> 0
A8: 4 | B8: Kattumannarkoil | C8: 159 | D8: 429 | E8: =C8+D8 -> 588 | F8: 412 | G8: =IFERROR(F8/J8,0) -> 0.89760349 | H8: 47 | I8: =IFERROR(H8/J8,0) -> 0.10239651 | J8: =F8+H8 -> 459 | K8: =E8-J8 -> 129 | L8: 129 | M8: 0 | N8: 0 | O8: =SUM(M8:N8) -> 0 | P8: =K8-SUM(L8:N8) -> 0
A9: 5 | B9: Kurinjipadi | C9: 185 | D9: 502 | E9: =C9+D9 -> 687 | F9: 432 | G9: =IFERROR(F9/J9,0) -> 0.85375494 | H9: 74 | I9: =IFERROR(H9/J9,0) -> 0.14624506 | J9: =F9+H9 -> 506 | K9: =E9-J9 -> 181 | L9: 181 | M9: 0 | N9: 0 | O9: =SUM(M9:N9) -> 0 | P9: =K9-SUM(L9:N9) -> 0
A10: 6 | B10: Panruti | C10: 215 | D10: 761 | E10: =C10+D10 -> 976 | F10: 558 | G10: =IFERROR(F10/J10,0) -> 0.77607789 | H10: 161 | I10: =IFERROR(H10/J10,0) -> 0.22392211 | J10: =F10+H10 -> 719 | K10: =E10-J10 -> 257 | L10: 248 | M10: 9 | N10: 0 | O10: =SUM(M10:N10) -> 9 | P10: =K10-SUM(L10:N10) -> 0
A11: 7 | B11: Srimushnam | C11: 88 | D11: 247 | E11: =C11+D11 -> 335 | F11: 236 | G11: =IFERROR(F11/J11,0) -> 0.91472868 | H11: 22 | I11: =IFERROR(H11/J11,0) -> 0.085271318 | J11: =F11+H11 -> 258 | K11: =E11-J11 -> 77 | L11: 77 | M11: 0 | N11: 0 | O11: =SUM(M11:N11) -> 0 | P11: =K11-SUM(L11:N11) -> 0
A12: 8 | B12: Titagudi | C12: 190 | D12: 634 | E12: =C12+D12 -> 824 | F12: 578 | G12: =IFERROR(F12/J12,0) -> 0.86011905 | H12: 94 | I12: =IFERROR(H12/J12,0) -> 0.13988095 | J12: =F12+H12 -> 672 | K12: =E12-J12 -> 152 | L12: 152 | M12: 0 | N12: 0 | O12: =SUM(M12:N12) -> 0 | P12: =K12-SUM(L12:N12) -> 0
A13: 9 | B13: Veppur | C13: 199 | D13: 524 | E13: =C13+D13 -> 723 | F13: 488 | G13: =IFERROR(F13/J13,0) -> 0.900369 | H13: 54 | I13: =IFERROR(H13/J13,0) -> 0.099630996 | J13: =F13+H13 -> 542 | K13: =E13-J13 -> 181 | L13: 180 | M13: 1 | N13: 0 | O13: =SUM(M13:N13) -> 1 | P13: =K13-SUM(L13:N13) -> 0
A14: 10 | B14: Vridhachalam | C14: 226 | D14: 527 | E14: =C14+D14 -> 753 | F14: 615 | G14: =IFERROR(F14/J14,0) -> 0.84246575 | H14: 115 | I14: =IFERROR(H14/J14,0) -> 0.15753425 | J14: =F14+H14 -> 730 | K14: =E14-J14 -> 23 | L14: 23 | M14: 0 | N14: 0 | O14: =SUM(M14:N14) -> 0 | P14: =K14-SUM(L14:N14) -> 0
B15: Total | C15: =SUM(C5:INDEX(C:C,ROW()-1)) -> 1601 | D15: =SUM(D5:INDEX(D:D,ROW()-1)) -> 5137 | E15: =C15+D15 -> 6738 | F15: =SUM(F5:INDEX(F:F,ROW()-1)) -> 4506 | G15: =IFERROR(F15/J15,0) -> 0.85276306 | H15: =SUM(H5:INDEX(H:H,ROW()-1)) -> 778 | I15: =IFERROR(H15/J15,0) -> 0.14723694 | J15: =F15+H15 -> 5284 | K15: =E15-J15 -> 1454 | L15: =SUM(L5:INDEX(L:L,ROW()-1)) -> 1433 | M15: =SUM(M5:INDEX(M:M,ROW()-1)) -> 10 | N15: =SUM(N5:INDEX(N:N,ROW()-1)) -> 0 | O15: =SUM(M15:N15) -> 10 | P15: =K15-SUM(L15:N15) -> 11
A17: Blue = typed data (edit these). Black = formula (do not type over). To add a taluk/town: insert a row ABOVE the Total row and copy the row above it; totals, checks and the Dashboard update automatically.

Sheet NISD RURAL TOP 5 REJECTION VILL
A1: TALUK WISE TOP 5 VAO VILLAGE REJECTION COUNT(NISD - RURAL) 01.09.2026 TO 30.09.2026
A2: S.No | B2: Taluk | C2: Village name | D2: Rejection count | E2: S.No | F2: Taluk | G2: Village name | H2: Rejection count
A3: 1 | B3: BHUVANAGIRI | C3: PINNALUR | D3: 7 | E3: 1 | F3: VRIDHACHALAM | G3: ERUMANR | H3: 6
A4: 2 | C4: ARIYAKOSTI | D4: 6 | E4: 2 | G4: MUTHANAI | H4: 6
A5: 3 | C5: MANJAKUZHI | D5: 6 | E5: 3 | G5: PERIYAVADAVADI | H5: 5
A6: 4 | C6: AGARAM | D6: 4 | E6: 4 | G6: AMMERI | H6: 4
A7: 5 | C7: MIRALUR | D7: 4 | E7: 5 | G7: ARASAKUZHI | H7: 4
A8: 1 | B8: CHIDAMBARAM | C8: KEEZHANUVAMPATTU | D8: 4 | E8: 1 | F8: VEPPUR | G8: IVATHUKUDI | H8: 5
A9: 2 | C9: B.MADUVANKARI | D9: 3 | E9: 2 | G9: JA.ENDHAL | H9: 4
A10: 3 | C10: MEDHIKUDI | D10: 3 | E10: 3 | G10: K.KOTHANUR | H10: 4
A11: 4 | C11: USUPUR | D11: 2 | E11: 4 | G11: THIRUPAYAR | H11: 4
A12: 5 | C12: UTHAMANCHOZHAMANGALAM | D12: 2 | E12: 5 | G12: ORANGUR | H12: 3
A13: 1 | B13: CUDDALORE | C13: KOTHANDARAMPURAM | D13: 6 | E13: 1 | F13: TITAKUDI | G13: PENNADAM | H13: 6
A14: 2 | C14: VELLAKARAI | D14: 6 | E14: 2 | G14: ERAIYUR | H14: 5
A15: 3 | C15: THIRUVANDHIPURAM | D15: 6 | E15: 3 | G15: VENKARUMBUR | H15: 5
A16: 4 | C16: KONDUR | D16: 4 | E16: 4 | G16: IRULAMPATTU | H16: 5
A17: 5 | C17: ARISIPERIYANKUPPAM | D17: 3 | E17: 5 | G17: THOZHTHUR | H17: 4
A18: 1 | B18: PANRUTI | C18: VEGAKOLLAI | D18: 21 | E18: 1 | F18: KATTUMANNARKOIL | G18: KUNAVASAL | H18: 4
A19: 2 | C19: VALLAM | D19: 14 | E19: 2 | G19: KARUNAKARANALLUR | H19: 3
A20: 3 | C20: MELMAMPATTU | D20: 9 | E20: 3 | G20: KURUNKUDI | H20: 3
A21: 4 | C21: MARUNGUR | D21: 8 | E21: 4 | G21: MELPAKATHURAI | H21: 3
A22: 5 | C22: SILAMBIANATHAPETTAI | D22: 7 | E22: 5 | G22: VEERANATHAPURAM | H22: 3
A23: 1 | B23: KURINJIPADI | C23: VADAKUTHU | D23: 10 | E23: 1 | F23: SRIMUSHNAM | G23: KAVANOOR | H23: 3
A24: 2 | C24: PARVATHIPURAM | D24: 9 | E24: 2 | G24: MARUNGUR | H24: 2
A25: 3 | C25: KEEZHUR | D25: 8 | E25: 3 | G25: NAGARAPPADI | H25: 2
A26: 4 | C26: VAZHUTHALAMPATTU | D26: 5 | E26: 4 | G26: VALLIYAM | H26: 2
A27: 5 | C27: PEIYAKKANATHAM | D27: 4 | E27: 5 | G27: SRINEDUCHERRY | H27: 2
A29: Blue = typed data. Keep the same layout (5 villages per taluk, taluk name on the first row of each block); the Dashboard's top-villages list reads rows 3 to 27.

Sheet NISD NATHAM
A1: NATHAM NISD OPT Report - 01-10-2026
A2: NO. OF Not Involving Subdivision APPLICATION FROM : 01-09-2026 - TO : 30-09-2026 *
A3: S.No | B3: Taluk | C3: Opening balance as on 01.09.2026 | D3: Received | E3: Transferred (out) | F3: Total | G3: Disposed | L3: Pending | M3: Pending breakup | P3: Pending beyond limit | Q3: Check: pending − breakup (should be 0)
G4: Approved | H4: % | I4: Rejected | J4: % | K4: Total disposed | M4: Below 15 days | N4: Over 15 days | O4: Over 1 month
A5: 1 | B5: Bhuvanagiri | C5: 101 | D5: 241 | E5: 4 | F5: =C5+D5-E5 -> 338 | G5: 181 | H5: =IFERROR(G5/K5,0) -> 0.70980392 | I5: 74 | J5: =IFERROR(I5/K5,0) -> 0.29019608 | K5: =G5+I5 -> 255 | L5: =F5-K5 -> 83 | M5: 83 | N5: 0 | O5: 0 | P5: =SUM(N5:O5) -> 0 | Q5: =L5-SUM(M5:O5) -> 0
A6: 2 | B6: Chidambaram | C6: 76 | D6: 244 | E6: 3 | F6: =C6+D6-E6 -> 317 | G6: 199 | H6: =IFERROR(G6/K6,0) -> 0.85775862 | I6: 33 | J6: =IFERROR(I6/K6,0) -> 0.14224138 | K6: =G6+I6 -> 232 | L6: =F6-K6 -> 85 | M6: 85 | N6: 0 | O6: 0 | P6: =SUM(N6:O6) -> 0 | Q6: =L6-SUM(M6:O6) -> 0
A7: 3 | B7: Cuddalore | C7: 68 | D7: 181 | E7: 10 | F7: =C7+D7-E7 -> 239 | G7: 139 | H7: =IFERROR(G7/K7,0) -> 0.79885057 | I7: 35 | J7: =IFERROR(I7/K7,0) -> 0.20114943 | K7: =G7+I7 -> 174 | L7: =F7-K7 -> 65 | M7: 65 | N7: 0 | O7: 0 | P7: =SUM(N7:O7) -> 0 | Q7: =L7-SUM(M7:O7) -> 0
A8: 4 | B8: Kattumannarkoil | C8: 85 | D8: 156 | E8: 9 | F8: =C8+D8-E8 -> 232 | G8: 142 | H8: =IFERROR(G8/K8,0) -> 0.85542169 | I8: 24 | J8: =IFERROR(I8/K8,0) -> 0.14457831 | K8: =G8+I8 -> 166 | L8: =F8-K8 -> 66 | M8: 66 | N8: 0 | O8: 0 | P8: =SUM(N8:O8) -> 0 | Q8: =L8-SUM(M8:O8) -> 0
A9: 5 | B9: Kurinjipadi | C9: 101 | D9: 146 | E9: 6 | F9: =C9+D9-E9 -> 241 | G9: 162 | H9: =IFERROR(G9/K9,0) -> 0.84816754 | I9: 29 | J9: =IFERROR(I9/K9,0) -> 0.15183246 | K9: =G9+I9 -> 191 | L9: =F9-K9 -> 50 | M9: 50 | N9: 0 | O9: 0 | P9: =SUM(N9:O9) -> 0 | Q9: =L9-SUM(M9:O9) -> 0
A10: 6 | B10: Panruti | C10: 111 | D10: 288 | E10: 10 | F10: =C10+D10-E10 -> 389 | G10: 228 | H10: =IFERROR(G10/K10,0) -> 0.78082192 | I10: 64 | J10: =IFERROR(I10/K10,0) -> 0.21917808 | K10: =G10+I10 -> 292 | L10: =F10-K10 -> 97 | M10: 97 | N10: 0 | O10: 0 | P10: =SUM(N10:O10) -> 0 | Q10: =L10-SUM(M10:O10) -> 0
A11: 7 | B11: Srimushnam | C11: 42 | D11: 83 | E11: 0 | F11: =C11+D11-E11 -> 125 | G11: 81 | H11: =IFERROR(G11/K11,0) -> 0.89010989 | I11: 10 | J11: =IFERROR(I11/K11,0) -> 0.10989011 | K11: =G11+I11 -> 91 | L11: =F11-K11 -> 34 | M11: 34 | N11: 0 | O11: 0 | P11: =SUM(N11:O11) -> 0 | Q11: =L11-SUM(M11:O11) -> 0
A12: 8 | B12: Titagudi | C12: 119 | D12: 241 | E12: 7 | F12: =C12+D12-E12 -> 353 | G12: 252 | H12: =IFERROR(G12/K12,0) -> 0.89361702 | I12: 30 | J12: =IFERROR(I12/K12,0) -> 0.10638298 | K12: =G12+I12 -> 282 | L12: =F12-K12 -> 71 | M12: 71 | N12: 0 | O12: 0 | P12: =SUM(N12:O12) -> 0 | Q12: =L12-SUM(M12:O12) -> 0
A13: 9 | B13: Veppur | C13: 79 | D13: 151 | E13: 3 | F13: =C13+D13-E13 -> 227 | G13: 149 | H13: =IFERROR(G13/K13,0) -> 0.85632184 | I13: 25 | J13: =IFERROR(I13/K13,0) -> 0.14367816 | K13: =G13+I13 -> 174 | L13: =F13-K13 -> 53 | M13: 53 | N13: 0 | O13: 0 | P13: =SUM(N13:O13) -> 0 | Q13: =L13-SUM(M13:O13) -> 0
A14: 10 | B14: Vridhachalam | C14: 111 | D14: 303 | E14: 4 | F14: =C14+D14-E14 -> 410 | G14: 218 | H14: =IFERROR(G14/K14,0) -> 0.81954887 | I14: 48 | J14: =IFERROR(I14/K14,0) -> 0.18045113 | K14: =G14+I14 -> 266 | L14: =F14-K14 -> 144 | M14: 144 | N14: 0 | O14: 0 | P14: =SUM(N14:O14) -> 0 | Q14: =L14-SUM(M14:O14) -> 0
B15: Total | C15: =SUM(C5:INDEX(C:C,ROW()-1)) -> 893 | D15: =SUM(D5:INDEX(D:D,ROW()-1)) -> 2034 | E15: =SUM(E5:INDEX(E:E,ROW()-1)) -> 56 | F15: =C15+D15-E15 -> 2871 | G15: =SUM(G5:INDEX(G:G,ROW()-1)) -> 1751 | H15: =IFERROR(G15/K15,0) -> 0.82477626 | I15: =SUM(I5:INDEX(I:I,ROW()-1)) -> 372 | J15: =IFERROR(I15/K15,0) -> 0.17522374 | K15: =G15+I15 -> 2123 | L15: =F15-K15 -> 748 | M15: =SUM(M5:INDEX(M:M,ROW()-1)) -> 748 | N15: =SUM(N5:INDEX(N:N,ROW()-1)) -> 0 | O15: =SUM(O5:INDEX(O:O,ROW()-1)) -> 0 | P15: =SUM(N15:O15) -> 0 | Q15: =L15-SUM(M15:O15) -> 0
A17: Blue = typed data (edit these). Black = formula (do not type over). To add a taluk/town: insert a row ABOVE the Total row and copy the row above it; totals, checks and the Dashboard update automatically.

Sheet NISD NATHAM TOP 5 REJECTION VIL
A1: TALUK WISE TOP 5 VAO VILLAGE REJECTION COUNT(NISD -NATHAM) 01.09.2026 TO 30.09.2026
A2: S.No | B2: Taluk | C2: Village name | D2: Rejection count | E2: S.No | F2: Taluk | G2: Village name | H2: Rejection count
A3: 1 | B3: BHUVANAGIRI | C3: Parangipettai | D3: 12 | E3: 1 | F3: VRIDHACHALAM | G3: Puliyur | H3: 4
A4: 2 | C4: Periyapattu | D4: 9 | E4: 2 | G4: Karuveppilankurichi | H4: 3
A5: 3 | C5: Manjakuzhi | D5: 9 | E5: 3 | G5: Komangalam | H5: 3
A6: 4 | C6: Poovalai West | D6: 4 | E6: 4 | G6: Kottumunai | H6: 3
A7: 5 | C7: Ariyakoshti | D7: 3 | E7: 5 | G7: Mangalam Ko | H7: 3
A8: 1 | B8: CHIDAMBARAM | C8: Usupur | D8: 5 | E8: 1 | F8: VEPPUR | G8: Ja.Endhal | H8: 4
A9: 2 | C9: Mugaiyur | D9: 3 | E9: 2 | G9: Sirupakkam | H9: 4
A10: 3 | C10: B.Maduvankarai | D10: 2 | E10: 3 | G10: Sirunesalur | H10: 4
A11: 4 | C11: C.Thandeawaranallur | D11: 2 | E11: 4 | G11: Mangalur | H11: 2
A12: 5 | C12: Keezhnatham | D12: 2 | E12: 5 | G12: Nagar | H12: 2
A13: 1 | B13: CUDDALORE | C13: Karamanikuppam | D13: 4 | E13: 1 | F13: TITAKUDI | G13: Venkarumbur | H13: 3
A14: 2 | C14: Ramapuram | D14: 4 | E14: 2 | G14: Leckur | H14: 2
A15: 3 | C15: Naduveerapattu | D15: 3 | E15: 3 | G15: Pennadam | H15: 2
A16: 4 | C16: Mathalapatti | D16: 3 | E16: 4 | G16: pattur | H16: 1
A17: 5 | C17: Vellakarai | D17: 2 | E17: 5 | G17: Pasar | H17: 1
A18: 1 | B18: PANRUTI | C18: Vallam | D18: 8 | E18: 1 | F18: KATTUMANNARKOIL | G18: Lalpeetai | H18: 3
A19: 2 | C19: Nadukuppam | D19: 7 | E19: 2 | G19: Rayanallur | H19: 2
A20: 3 | C20: Visur | D20: 5 | E20: 3 | G20: Mannarkudi | H20: 2
A21: 4 | C21: Vegakollai | D21: 4 | E21: 4 | G21: Chettithangal | H21: 2
A22: 5 | C22: Kilkangayankuppam | D22: 4 | E22: 5 | G22: Udiyakudi | H22: 2
A23: 1 | B23: KURINJIPADI | C23: Parvathipuram | D23: 3 | E23: 1 | F23: SRIMUSHNAM | G23: Kavanoor | H23: 3
A24: 2 | C24: Ambalavananpettai | D24: 2 | E24: 2 | G24: Devangudi | H24: 1
A25: 3 | C25: Ellapenpettai | D25: 2 | E25: 3 | G25: Srivakkaramari | H25: 1
A26: 4 | C26: Kundiyamallur North | D26: 2 | E26: 4 | G26: Srineduncherry | H26: 1
A27: 5 | C27: AdurAgram | D27: 2 | E27: 5 | G27: Ramapuram | H27: 1
A29: Blue = typed data. Keep the same layout (5 villages per taluk, taluk name on the first row of each block); the Dashboard's top-villages list reads rows 3 to 27.

Sheet URBAN NISD
A1: Cuddalore District URBAN NISD Application Progress (01.09.2026 to 30.09.2026)
A2: S No. Taluk Town Opening Balance Receipt Total Disposed Pending < 15 Days > 15 Days Over 1 Month
A3: S.No | B3: Taluk | C3: Town | D3: Opening balance | E3: Received | F3: Total | G3: Disposed | L3: Pending | M3: Pending breakup | P3: Pending beyond limit | Q3: Check: pending − breakup (should be 0)
G4: Approved | H4: % | I4: Rejected | J4: % | K4: Total disposed | M4: < 15 days | N4: > 15 days | O4: Over 1 month
A5: 1 | B5: Chidambaram | C5: Chidambaram | D5: 34 | E5: 64 | F5: =D5+E5 -> 98 | G5: 70 | H5: =IFERROR(G5/K5,0) -> 0.86419753 | I5: 11 | J5: =IFERROR(I5/K5,0) -> 0.13580247 | K5: =G5+I5 -> 81 | L5: =F5-K5 -> 17 | M5: 17 | N5: 0 | O5: 0 | P5: =SUM(N5:O5) -> 0 | Q5: =L5-SUM(M5:O5) -> 0
A6: 2 | B6: Cuddalore | C6: Cuddalore | D6: 69 | E6: 177 | F6: =D6+E6 -> 246 | G6: 140 | H6: =IFERROR(G6/K6,0) -> 0.78212291 | I6: 39 | J6: =IFERROR(I6/K6,0) -> 0.21787709 | K6: =G6+I6 -> 179 | L6: =F6-K6 -> 67 | M6: 67 | N6: 0 | O6: 0 | P6: =SUM(N6:O6) -> 0 | Q6: =L6-SUM(M6:O6) -> 0
A7: 3 | B7: Panruti | C7: Nellikuppam | D7: 25 | E7: 123 | F7: =D7+E7 -> 148 | G7: 99 | H7: =IFERROR(G7/K7,0) -> 0.88392857 | I7: 13 | J7: =IFERROR(I7/K7,0) -> 0.11607143 | K7: =G7+I7 -> 112 | L7: =F7-K7 -> 36 | M7: 36 | N7: 0 | O7: 0 | P7: =SUM(N7:O7) -> 0 | Q7: =L7-SUM(M7:O7) -> 0
A8: 4 | B8: Panruti | C8: Panruti | D8: 7 | E8: 160 | F8: =D8+E8 -> 167 | G8: 149 | H8: =IFERROR(G8/K8,0) -> 0.89221557 | I8: 18 | J8: =IFERROR(I8/K8,0) -> 0.10778443 | K8: =G8+I8 -> 167 | L8: =F8-K8 -> 0 | M8: 0 | N8: 0 | O8: 0 | P8: =SUM(N8:O8) -> 0 | Q8: =L8-SUM(M8:O8) -> 0
A9: 5 | B9: Virudhachalam | C9: Virudhachalam | D9: 131 | E9: 234 | F9: =D9+E9 -> 365 | G9: 208 | H9: =IFERROR(G9/K9,0) -> 0.79389313 | I9: 54 | J9: =IFERROR(I9/K9,0) -> 0.20610687 | K9: =G9+I9 -> 262 | L9: =F9-K9 -> 103 | M9: 103 | N9: 0 | O9: 0 | P9: =SUM(N9:O9) -> 0 | Q9: =L9-SUM(M9:O9) -> 0
B10: District Wise Total | D10: =SUM(D5:INDEX(D:D,ROW()-1)) -> 266 | E10: =SUM(E5:INDEX(E:E,ROW()-1)) -> 758 | F10: =D10+E10 -> 1024 | G10: =SUM(G5:INDEX(G:G,ROW()-1)) -> 666 | H10: =IFERROR(G10/K10,0) -> 0.83146067 | I10: =SUM(I5:INDEX(I:I,ROW()-1)) -> 135 | J10: =IFERROR(I10/K10,0) -> 0.16853933 | K10: =G10+I10 -> 801 | L10: =F10-K10 -> 223 | M10: =SUM(M5:INDEX(M:M,ROW()-1)) -> 223 | N10: =SUM(N5:INDEX(N:N,ROW()-1)) -> 0 | O10: =SUM(O5:INDEX(O:O,ROW()-1)) -> 0 | P10: =SUM(N10:O10) -> 0 | Q10: =L10-SUM(M10:O10) -> 0
A12: Blue = typed data (edit these). Black = formula (do not type over). To add a taluk/town: insert a row ABOVE the Total row and copy the row above it; totals, checks and the Dashboard update automatically.

Sheet ISD RURAL
A1: RURAL ISD REPORT WITH PERCENTAGE AS ON : 01-10-2026
A2: Periodicity : Date Range TRANSACTIONS FROM : 01-09-2026 - TO :30-09-2026 *
A3: S.No | B3: Division | C3: Taluk | D3: Opening balance on 01.09.2026 | E3: Received | F3: Total | G3: Disposed | L3: Pending | M3: Pending breakup | P3: Pending beyond limit | Q3: Check: pending − breakup (should be 0)
G4: Approved | H4: % | I4: Rejected | J4: % | K4: Total disposed | M4: Below 1 month | N4: Over 1 month | O4: Over 2 months
A5: 1 | B5: CUDDALORE | C5: Cuddalore | D5: 454 | E5: 515 | F5: =D5+E5 -> 969 | G5: 493 | H5: =IFERROR(G5/K5,0) -> 0.81085526 | I5: 115 | J5: =IFERROR(I5/K5,0) -> 0.18914474 | K5: =G5+I5 -> 608 | L5: =F5-K5 -> 361 | M5: 361 | N5: 0 | O5: 0 | P5: =SUM(N5:O5) -> 0 | Q5: =L5-SUM(M5:O5) -> 0
A6: 2 | B6: CUDDALORE | C6: Panruti | D6: 515 | E6: 515 | F6: =D6+E6 -> 1030 | G6: 430 | H6: =IFERROR(G6/K6,0) -> 0.81439394 | I6: 98 | J6: =IFERROR(I6/K6,0) -> 0.18560606 | K6: =G6+I6 -> 528 | L6: =F6-K6 -> 502 | M6: 488 | N6: 14 | O6: 0 | P6: =SUM(N6:O6) -> 14 | Q6: =L6-SUM(M6:O6) -> 0
A7: 3 | B7: CUDDALORE | C7: Kurinjipadi | D7: 352 | E7: 560 | F7: =D7+E7 -> 912 | G7: 400 | H7: =IFERROR(G7/K7,0) -> 0.79840319 | I7: 101 | J7: =IFERROR(I7/K7,0) -> 0.20159681 | K7: =G7+I7 -> 501 | L7: =F7-K7 -> 411 | M7: 406 | N7: 5 | O7: 0 | P7: =SUM(N7:O7) -> 5 | Q7: =L7-SUM(M7:O7) -> 0
A8: 4 | B8: CHIDAMBARAM | C8: Chidambaram | D8: 353 | E8: 495 | F8: =D8+E8 -> 848 | G8: 391 | H8: =IFERROR(G8/K8,0) -> 0.83191489 | I8: 79 | J8: =IFERROR(I8/K8,0) -> 0.16808511 | K8: =G8+I8 -> 470 | L8: =F8-K8 -> 378 | M8: 378 | N8: 0 | O8: 0 | P8: =SUM(N8:O8) -> 0 | Q8: =L8-SUM(M8:O8) -> 0
A9: 5 | B9: CHIDAMBARAM | C9: Bhuvanagiri | D9: 295 | E9: 323 | F9: =D9+E9 -> 618 | G9: 266 | H9: =IFERROR(G9/K9,0) -> 0.82352941 | I9: 57 | J9: =IFERROR(I9/K9,0) -> 0.17647059 | K9: =G9+I9 -> 323 | L9: =F9-K9 -> 295 | M9: 286 | N9: 9 | O9: 0 | P9: =SUM(N9:O9) -> 9 | Q9: =L9-SUM(M9:O9) -> 0
A10: 6 | B10: CHIDAMBARAM | C10: Srimushnam | D10: 114 | E10: 141 | F10: =D10+E10 -> 255 | G10: 126 | H10: =IFERROR(G10/K10,0) -> 0.91970803 | I10: 11 | J10: =IFERROR(I10/K10,0) -> 0.080291971 | K10: =G10+I10 -> 137 | L10: =F10-K10 -> 118 | M10: 117 | N10: 1 | O10: 0 | P10: =SUM(N10:O10) -> 1 | Q10: =L10-SUM(M10:O10) -> 0
A11: 7 | B11: CHIDAMBARAM | C11: Kattumannarkoil | D11: 300 | E11: 388 | F11: =D11+E11 -> 688 | G11: 314 | H11: =IFERROR(G11/K11,0) -> 0.90751445 | I11: 32 | J11: =IFERROR(I11/K11,0) -> 0.092485549 | K11: =G11+I11 -> 346 | L11: =F11-K11 -> 342 | M11: 336 | N11: 6 | O11: 0 | P11: =SUM(N11:O11) -> 6 | Q11: =L11-SUM(M11:O11) -> 0
A12: 8 | B12: VRIDHACHALAM | C12: Vridhachalam | D12: 412 | E12: 457 | F12: =D12+E12 -> 869 | G12: 364 | H12: =IFERROR(G12/K12,0) -> 0.8161435 | I12: 82 | J12: =IFERROR(I12/K12,0) -> 0.1838565 | K12: =G12+I12 -> 446 | L12: =F12-K12 -> 423 | M12: 423 | N12: 0 | O12: 0 | P12: =SUM(N12:O12) -> 0 | Q12: =L12-SUM(M12:O12) -> 0
A13: 9 | B13: VRIDHACHALAM | C13: Titagudi | D13: 277 | E13: 250 | F13: =D13+E13 -> 527 | G13: 215 | H13: =IFERROR(G13/K13,0) -> 0.87044534 | I13: 32 | J13: =IFERROR(I13/K13,0) -> 0.12955466 | K13: =G13+I13 -> 247 | L13: =F13-K13 -> 280 | M13: 280 | N13: 0 | O13: 0 | P13: =SUM(N13:O13) -> 0 | Q13: =L13-SUM(M13:O13) -> 0
A14: 10 | B14: VRIDHACHALAM | C14: Veppur | D14: 343 | E14: 326 | F14: =D14+E14 -> 669 | G14: 292 | H14: =IFERROR(G14/K14,0) -> 0.85630499 | I14: 49 | J14: =IFERROR(I14/K14,0) -> 0.14369501 | K14: =G14+I14 -> 341 | L14: =F14-K14 -> 328 | M14: 326 | N14: 2 | O14: 0 | P14: =SUM(N14:O14) -> 2 | Q14: =L14-SUM(M14:O14) -> 0
C15: Total | D15: =SUM(D5:INDEX(D:D,ROW()-1)) -> 3415 | E15: =SUM(E5:INDEX(E:E,ROW()-1)) -> 3970 | F15: =D15+E15 -> 7385 | G15: =SUM(G5:INDEX(G:G,ROW()-1)) -> 3291 | H15: =IFERROR(G15/K15,0) -> 0.83379782 | I15: =SUM(I5:INDEX(I:I,ROW()-1)) -> 656 | J15: =IFERROR(I15/K15,0) -> 0.16620218 | K15: =G15+I15 -> 3947 | L15: =F15-K15 -> 3438 | M15: =SUM(M5:INDEX(M:M,ROW()-1)) -> 3401 | N15: =SUM(N5:INDEX(N:N,ROW()-1)) -> 37 | O15: =SUM(O5:INDEX(O:O,ROW()-1)) -> 0 | P15: =SUM(N15:O15) -> 37 | Q15: =L15-SUM(M15:O15) -> 0
A17: Blue = typed data (edit these). Black = formula (do not type over). To add a taluk/town: insert a row ABOVE the Total row and copy the row above it; totals, checks and the Dashboard update automatically.

Sheet ISD RURAL TOP 5VILLAGES
A1: TALUK WISE TOP 5 VAO VILLAGE REJECTION COUNT(ISD - RURAL) 01.09.2026 to 30.09.2026
A2: S.No | B2: Taluk | C2: Village name | D2: Rejection count | E2: S.No | F2: Taluk | G2: Village name | H2: Rejection count
A3: 1 | B3: BHUVANAGIRI | C3: ARIYAKOSHTI | D3: 9 | E3: 1 | F3: VRIDHACHALAM | G3: KAMMAPURAM | H3: 6
A4: 2 | C4: PINNALUR | D4: 4 | E4: 2 | G4: KARKUDAL | H4: 4
A5: 3 | C5: SATHAPPADI | D5: 3 | E5: 3 | G5: EDAIYUR | H5: 4
A6: 4 | C6: SETHIYATHOPE | D6: 3 | E6: 4 | G6: CHINNAPARUR | H6: 3
A7: 5 | C7: VADAKRISHNAPURAM | D7: 3 | E7: 5 | G7: M.AGARAM | H7: 3
A8: 1 | B8: CHIDAMBARAM | C8: C.KOTHANKUDI | D8: 6 | E8: 1 | F8: VEPPUR | G8: NAGAR | H8: 5
A9: 2 | C9: PARAMESHVARANALLUR | D9: 6 | E9: 2 | G9: SEPPAKKAM | H9: 4
A10: 3 | C10: LALPURAM | D10: 5 | E10: 3 | G10: SIRUNASALUR | H10: 4
A11: 4 | C11: MTIKUDI | D11: 5 | E11: 4 | G11: PODAIYUR | H11: 3
A12: 5 | C12: USUPPUR | D12: 5 | E12: 5 | G12: IVADHUKUDI | H12: 3
A13: 1 | B13: CUDDALORE | C13: VELLAKARAI | D13: 10 | E13: 1 | F13: TITAKUDI | G13: THOZHUTUR | H13: 5
A14: 2 | C14: NATHAPATTU | D14: 7 | E14: 2 | G14: MALIGAIKOTTAM | H14: 3
A15: 3 | C15: NADUVEERAPATTU | D15: 6 | E15: 3 | G15: M.PUDAIYUR | H15: 3
A16: 4 | C16: PACHAIYANKUPPAM | D16: 5 | E16: 4 | G16: RAMANATHAM | H16: 3
A17: 5 | C17: SEDDAPALAYAM | D17: 4 | E17: 5 | G17: THACHUR | H17: 2
A18: 1 | B18: PANRUTI | C18: VEGAKOLLAI | D18: 10 | E18: 1 | F18: KATTUMANNARKOIL | G18: LALPETTAI | H18: 4
A19: 2 | C19: MALIGAMPATTU | D19: 9 | E19: 2 | G19: MELAPAKKATHURAI | H19: 3
A20: 3 | C20: SILAMBINATHANPETTAI | D20: 5 | E20: 3 | G20: THIRUMOOLASTHANAM | H20: 2
A21: 4 | C21: MARUNGUR | D21: 5 | E21: 4 | G21: KUPPAPILLAICHAVADI | H21: 2
A22: 5 | C22: MELMAMPATTU | D22: 4 | E22: 5 | G22: VEERANANALLUR | H22: 2
A23: 1 | B23: KURINJIPADI | C23: VADAKUTHU | D23: 18 | E23: 1 | F23: SRIMUSHNAM | G23: CHOLATHARAM | H23: 4
A24: 2 | C24: VAZUTHALAMPATTU | D24: 8 | E24: 2 | G24: MATHAKALIRMANIKAM | H24: 2
A25: 3 | C25: SERAKUPPAM | D25: 7 | E25: 3 | G25: SRINEDUCHERRY | H25: 1
A26: 4 | C26: PARVATHIPURAM | D26: 6 | E26: 4 | G26: NANGUDI | H26: 1
A27: 5 | C27: KANNADY | D27: 6 | E27: 5 | G27: PALAYAMKOTTIKEELPATHI | H27: 1
A29: Blue = typed data. Keep the same layout (5 villages per taluk, taluk name on the first row of each block); the Dashboard's top-villages list reads rows 3 to 27.

Sheet ISD VAO &NATHAM 
A1: RURAL ISD REPORT WITH PERCENTAGE AS ON : 01-10-2026 (surveyor vs VAO)
A2: Periodicity : Date Range TRANSACTIONS FROM : 01-09-2026 - TO : 30-09-2026 *
A3: S.No | B3: Taluk | C3: District total (from ISD RURAL) | K3: Pending | L3: Surveyor | Q3: VAO | V3: Check: surveyor + VAO − district (should be 0)
C4: Opening balance | D4: Received | E4: Total | F4: Approved | G4: % | H4: Rejected | I4: % | J4: Total disposed | L4: Approved | M4: % | N4: Rejected | O4: % | P4: Total disposed | Q4: Approved | R4: % | S4: Rejected | T4: % | U4: Total disposed
A5: 1 | B5: Cuddalore | C5: =SUMIF('ISD RURAL'!$C:$C,$B5,'ISD RURAL'!$D:$D) -> 454 | D5: =SUMIF('ISD RURAL'!$C:$C,$B5,'ISD RURAL'!$E:$E) -> 515 | E5: =SUMIF('ISD RURAL'!$C:$C,$B5,'ISD RURAL'!$F:$F) -> 969 | F5: =SUMIF('ISD RURAL'!$C:$C,$B5,'ISD RURAL'!$G:$G) -> 493 | G5: =IFERROR(F5/J5,0) -> 0.81085526 | H5: =SUMIF('ISD RURAL'!$C:$C,$B5,'ISD RURAL'!$I:$I) -> 115 | I5: =IFERROR(H5/J5,0) -> 0.18914474 | J5: =SUMIF('ISD RURAL'!$C:$C,$B5,'ISD RURAL'!$K:$K) -> 608 | K5: =SUMIF('ISD RURAL'!$C:$C,$B5,'ISD RURAL'!$L:$L) -> 361 | L5: 457 | M5: =IFERROR(L5/$J5,0) -> 0.75164474 | N5: 99 | O5: =IFERROR(N5/$J5,0) -> 0.16282895 | P5: =L5+N5 -> 556 | Q5: 36 | R5: =IFERROR(Q5/$J5,0) -> 0.059210526 | S5: 16 | T5: =IFERROR(S5/$J5,0) -> 0.026315789 | U5: =Q5+S5 -> 52 | V5: =ABS(L5+Q5-F5)+ABS(N5+S5-H5) -> 0
A6: 2 | B6: Panruti | C6: =SUMIF('ISD RURAL'!$C:$C,$B6,'ISD RURAL'!$D:$D) -> 515 | D6: =SUMIF('ISD RURAL'!$C:$C,$B6,'ISD RURAL'!$E:$E) -> 515 | E6: =SUMIF('ISD RURAL'!$C:$C,$B6,'ISD RURAL'!$F:$F) -> 1030 | F6: =SUMIF('ISD RURAL'!$C:$C,$B6,'ISD RURAL'!$G:$G) -> 430 | G6: =IFERROR(F6/J6,0) -> 0.81439394 | H6: =SUMIF('ISD RURAL'!$C:$C,$B6,'ISD RURAL'!$I:$I) -> 98 | I6: =IFERROR(H6/J6,0) -> 0.18560606 | J6: =SUMIF('ISD RURAL'!$C:$C,$B6,'ISD RURAL'!$K:$K) -> 528 | K6: =SUMIF('ISD RURAL'!$C:$C,$B6,'ISD RURAL'!$L:$L) -> 502 | L6: 404 | M6: =IFERROR(L6/$J6,0) -> 0.76515152 | N6: 90 | O6: =IFERROR(N6/$J6,0) -> 0.17045455 | P6: =L6+N6 -> 494 | Q6: 26 | R6: =IFERROR(Q6/$J6,0) -> 0.049242424 | S6: 8 | T6: =IFERROR(S6/$J6,0) -> 0.015151515 | U6: =Q6+S6 -> 34 | V6: =ABS(L6+Q6-F6)+ABS(N6+S6-H6) -> 0
A7: 3 | B7: Kurinjipadi | C7: =SUMIF('ISD RURAL'!$C:$C,$B7,'ISD RURAL'!$D:$D) -> 352 | D7: =SUMIF('ISD RURAL'!$C:$C,$B7,'ISD RURAL'!$E:$E) -> 560 | E7: =SUMIF('ISD RURAL'!$C:$C,$B7,'ISD RURAL'!$F:$F) -> 912 | F7: =SUMIF('ISD RURAL'!$C:$C,$B7,'ISD RURAL'!$G:$G) -> 400 | G7: =IFERROR(F7/J7,0) -> 0.79840319 | H7: =SUMIF('ISD RURAL'!$C:$C,$B7,'ISD RURAL'!$I:$I) -> 101 | I7: =IFERROR(H7/J7,0) -> 0.20159681 | J7: =SUMIF('ISD RURAL'!$C:$C,$B7,'ISD RURAL'!$K:$K) -> 501 | K7: =SUMIF('ISD RURAL'!$C:$C,$B7,'ISD RURAL'!$L:$L) -> 411 | L7: 368 | M7: =IFERROR(L7/$J7,0) -> 0.73453094 | N7: 85 | O7: =IFERROR(N7/$J7,0) -> 0.16966068 | P7: =L7+N7 -> 453 | Q7: 32 | R7: =IFERROR(Q7/$J7,0) -> 0.063872255 | S7: 16 | T7: =IFERROR(S7/$J7,0) -> 0.031936128 | U7: =Q7+S7 -> 48 | V7: =ABS(L7+Q7-F7)+ABS(N7+S7-H7) -> 0
A8: 4 | B8: Chidambaram | C8: =SUMIF('ISD RURAL'!$C:$C,$B8,'ISD RURAL'!$D:$D) -> 353 | D8: =SUMIF('ISD RURAL'!$C:$C,$B8,'ISD RURAL'!$E:$E) -> 495 | E8: =SUMIF('ISD RURAL'!$C:$C,$B8,'ISD RURAL'!$F:$F) -> 848 | F8: =SUMIF('ISD RURAL'!$C:$C,$B8,'ISD RURAL'!$G:$G) -> 391 | G8: =IFERROR(F8/J8,0) -> 0.83191489 | H8: =SUMIF('ISD RURAL'!$C:$C,$B8,'ISD RURAL'!$I:$I) -> 79 | I8: =IFERROR(H8/J8,0) -> 0.16808511 | J8: =SUMIF('ISD RURAL'!$C:$C,$B8,'ISD RURAL'!$K:$K) -> 470 | K8: =SUMIF('ISD RURAL'!$C:$C,$B8,'ISD RURAL'!$L:$L) -> 378 | L8: 293 | M8: =IFERROR(L8/$J8,0) -> 0.62340426 | N8: 57 | O8: =IFERROR(N8/$J8,0) -> 0.1212766 | P8: =L8+N8 -> 350 | Q8: 98 | R8: =IFERROR(Q8/$J8,0) -> 0.20851064 | S8: 22 | T8: =IFERROR(S8/$J8,0) -> 0.046808511 | U8: =Q8+S8 -> 120 | V8: =ABS(L8+Q8-F8)+ABS(N8+S8-H8) -> 0
A9: 5 | B9: Bhuvanagiri | C9: =SUMIF('ISD RURAL'!$C:$C,$B9,'ISD RURAL'!$D:$D) -> 295 | D9: =SUMIF('ISD RURAL'!$C:$C,$B9,'ISD RURAL'!$E:$E) -> 323 | E9: =SUMIF('ISD RURAL'!$C:$C,$B9,'ISD RURAL'!$F:$F) -> 618 | F9: =SUMIF('ISD RURAL'!$C:$C,$B9,'ISD RURAL'!$G:$G) -> 266 | G9: =IFERROR(F9/J9,0) -> 0.82352941 | H9: =SUMIF('ISD RURAL'!$C:$C,$B9,'ISD RURAL'!$I:$I) -> 57 | I9: =IFERROR(H9/J9,0) -> 0.17647059 | J9: =SUMIF('ISD RURAL'!$C:$C,$B9,'ISD RURAL'!$K:$K) -> 323 | K9: =SUMIF('ISD RURAL'!$C:$C,$B9,'ISD RURAL'!$L:$L) -> 295 | L9: 209 | M9: =IFERROR(L9/$J9,0) -> 0.64705882 | N9: 35 | O9: =IFERROR(N9/$J9,0) -> 0.10835913 | P9: =L9+N9 -> 244 | Q9: 57 | R9: =IFERROR(Q9/$J9,0) -> 0.17647059 | S9: 22 | T9: =IFERROR(S9/$J9,0) -> 0.068111455 | U9: =Q9+S9 -> 79 | V9: =ABS(L9+Q9-F9)+ABS(N9+S9-H9) -> 0
A10: 6 | B10: Srimushnam | C10: =SUMIF('ISD RURAL'!$C:$C,$B10,'ISD RURAL'!$D:$D) -> 114 | D10: =SUMIF('ISD RURAL'!$C:$C,$B10,'ISD RURAL'!$E:$E) -> 141 | E10: =SUMIF('ISD RURAL'!$C:$C,$B10,'ISD RURAL'!$F:$F) -> 255 | F10: =SUMIF('ISD RURAL'!$C:$C,$B10,'ISD RURAL'!$G:$G) -> 126 | G10: =IFERROR(F10/J10,0) -> 0.91970803 | H10: =SUMIF('ISD RURAL'!$C:$C,$B10,'ISD RURAL'!$I:$I) -> 11 | I10: =IFERROR(H10/J10,0) -> 0.080291971 | J10: =SUMIF('ISD RURAL'!$C:$C,$B10,'ISD RURAL'!$K:$K) -> 137 | K10: =SUMIF('ISD RURAL'!$C:$C,$B10,'ISD RURAL'!$L:$L) -> 118 | L10: 90 | M10: =IFERROR(L10/$J10,0) -> 0.65693431 | N10: 6 | O10: =IFERROR(N10/$J10,0) -> 0.04379562 | P10: =L10+N10 -> 96 | Q10: 36 | R10: =IFERROR(Q10/$J10,0) -> 0.26277372 | S10: 5 | T10: =IFERROR(S10/$J10,0) -> 0.03649635 | U10: =Q10+S10 -> 41 | V10: =ABS(L10+Q10-F10)+ABS(N10+S10-H10) -> 0
